Workbook

Sheet Introduction et instructions
B6: 45805
B8: Introduction et présentation du deck
B9: INTRODUCTION AU DOCUMENT
B10: Suite au rachat de Boardriders, le groupe Beaumanoir a mandaté une étude pour le choix d'un nouvel ERP "opérations achat et vente" commun à l’ensemble des entités du Groupe. La présente consultation est lancée auprès d'éditeurs pré-sélectionnés, afin de collecter et comparer les informations sur leurs solutions. Ce questionnaire a pour but de collecter et évaluer ces données sur une base unifiée, construite à partir des attentes et besoins du Groupe Beaumanoir. Nous vous demandons, par conséquent, de reporter vos réponses directement dans les onglets de ce document.
B18: 0. PRESENTATION DE LA SOLUTION
B19: Cet onglet vise à recueillir les informations générales sur votre entreprise et sur l’ERP que vous proposez. Une zone de commentaire libre est prévue à la fin de l’onglet pour vous permettre de nous transmettre toute information complémentaire que vous jugerez pertinente : éléments différenciateurs, contexte d’évolution de votre solution, précisions techniques, etc.
B24: 1. BESOINS FONCTIONNELS
B25: Cet onglet présente les besoins fonctionnels exprimés par les référents métiers du groupe Beaumanoir. Le questionnaire qui s'y trouve doit permettre de confirmer la capacité de la solution à répondre à chacun des besoins, unitairement. Instructions : Chaque ligne correspond à l'un des besoins exprimés par les métiers, qu'il s'agisse d'une fonctionnalité, de critères et d'attributs de gestion ou de paramétrage, ou d'une règle de gestion particulière. Les besoins considérés très standards (ex : création d'un nouvel article, saisie d'une commande de vente) ont été ignorés. Ils sont réputés couverts par tous les ERP de la place. Merci de saisir votre réponse dans les deux champs prévus à cet effet. - Réponse (colonne E) : sélectionner la valeur adéquate parmi les options proposées YES. Couvert en standard (100%) CUS. Couvert avec customization DEV. Développement spécifiques requis TPS. Couvert par application tierce (au catalogue éditeur) FUT. En développement pour release / version ultérieure NON. Non couvert - Estimation coûts supp. (colonne F) : dans le cas où le besoin serait couvert par des développements spécifiques ou de la customization, estimer si possible le coût complémentaire (qui sera ajouté aux estimations budgétaies). - Réponse - compléments (colonne G). - Justifier, si nécessaire / pertinent, votre répons codifiée - Quelques précisions utiles sur les compléments de réponse. - Tout complément d'information est appréciable pour évaluer la qualité de la couverture. - Nous avons ajouté une mention "merci de détailler votre réponse" en face des critères pour lesquels des précisions sont vivement souhaitées. - En cas de réponse partielle au besoin - avec customization, ou développement - merci d'indiquer les limites rencontrées en standard par la solution, et le périmètre des travaux d'adaptation. Nota : nous avons choisi de ne pas donner de référence particulière à chaque ligne (1., 1.1, 1.1.1, etc.) afin de limiter la complexité de lecture. Vous pourrez faire directement référence au numéro de ligne dans nos échanges éventuels. N’hésitez pas à nous contacter pour toute question complémentaire ou besoin de clarification.
B55: 2. INTERFACES
B56: Cet onglet présente les opportunités d'interfaçage entre l'ERP à choisir et les principales applications de l'écosystème du groupe (marques historiques et Boardriders). Le questionnaire doit permettre de recenser les éventuels connecteurs et interfaces pré-développés / pré-paramétrés existants, susceptibles de simplifier la connexion entre systèmes. A noter : certaines applications apparaissent en doublon car elles remplissent les mêmes usages (ex : deux CRM). Ceci est du au fait que les systèmes historiques du groupe et ceux de Boardriders sont aujourd'hui distincts. Le choix des applications conservées sur chacun des domaines n'est pas arrêté et pourrait être influencé par la facilité d'interfaçage. Instructions : Chaque ligne correspond à l'une des applications de l'écosystème actuel du Groupe Beaumanoir. - Réponse (colonne G) : sélectionner la valeur adéquate parmi les options proposées STD. Connecteur standard existant => pas de développement, paramétrage minimal CUS. Connecteur spécifique existant => connecteur spécifique réalisé dans le cadre d'un précédent déploiement, réutilisable moyennant des adaptations / customisation DEV. Interface spécifique à développer => interface à créer en totalité NON. Non couvert => pas d'interfaçage possible - Estimation coûts supp. (colonne H) : estimer la charge de paramétrage / adaptation, ou de développement, pour chaque interface. - Limites de transfert (colonne I) Indiquer, pour chaque interface, si des limites en matière de volumétrie sont à prévoir. Ces limites peuvent être intrinsèques à l'ERP (nombre de lignes limité en entrée), liés à l'interface (technologie utilisée pour interfacer cet outil) ou aux performances (pas de limite de volume, mais temps de traitement trop important pour un batch), par exemple. - Détail des limites de transfert (colonne J). Détailler les limites de transfert : cause, volume maximum.
B81: 3. ARCHITECTURE ET SECURITE
B82: Cet onglet reprend les principaux besoins non fonctionnels que doit couvrir l'ERP. Le questionnaire permet de mieux comprendre les aspects techniques de votre solution (modalité, sécurité, conformité, propriété des données). Instructions : Chaque ligne correspond à une question ou un critère. Saisissez ou sélectionnez la valeur adéquate dans le champ "réponse" (colonne D).
B89: 4. VOLUMETRIE
... B114: Cet onglet doit permettre de collecter de premières estimations macroscopiques, à partir d'abaques et de quelques données relatives au contexte du Groupe Beaumanoir, pour positionner la solution dans une fourchette de prix (dans l'absolu, et par rapport aux autres candidats). il ne s'agit pas d'une propositon commerciale, et les estimations faites ici n'ont pas vocation à se substituer à une propositon en bonne et due forme. Rappel des éléments de contexte du Groupe Beaumanoir susceptibles d'impacter les coûts de déploiement et récurrents. - 15 marques. - Multi-sociétés, multi-canaux, multi-devises, clients français et internationaux. - Volumes important de données référentielles et de transactions (voir ANNEXE 1 - Volumétrie GBM). - 8 instances de STORELAND et 1 instance SAP (globale Boardriders) dont les données sont à reprendre et migrer. - Une dizaine d'interfaces avec les applications existantes du Groupe (ce chiffre sera affiné ultérieurement). - Un fort niveau de customization / personnalisation des règles de gestion attendu, notamment sur : - la gestion des stocks, - la gestion des règles de réassort (déclenchement, calcul du cloisage / des optimums logistiques (colis / bag VS picking)), - la gestion des allocations, et notamment les critères de calcul des priorités et de blocage. - Un fort niveau d'automatisation / simplification dans le traitement en masse de certaines données (recherche et gestion de commandes d'achat). - Le paramétrage / la customization de cockpits et d'outils d'aide au pilotage et à la décision (permettant des simulations et comparaison de scénarios). Instructions : Veuillez saisir les réponses adéquates dans le champ "estimations en K€" (colonne C) et "réponse" (colonne C). Les cases en bleu ciel sont des cellules de calcul dans lesquelles nous vous demandons de ne rien saisir. A noter : nous ne reprenons pas automatiquement les estimations de coûts complémentaires renseignées dans les onglets 1. Besoins fonctionnels (colonne F) et 2. Interfaces (colonne G), pour vous permettre de réaliser les optimisations adéquates. Les estimations en ligne 5 (customization et développements spécifiques) et 6 (connecteurs et interfaces) doivent tout de même être considérées dans le calcul, puisque parties intégrantes de la couverture du besoin.

Sheet 0. Informations générales
A1: DOMAINE | B1: QUESTION | C1: REPONSE | D1: COMMENTAIRE (facultatif)
A2: Informations générales sur la société éditrice | B2: Nom de l’entreprise éditrice | C2: Sap
B3: Chiffre d’affaires annuel total | C3: 34,18 milliards d'euros | D3: Revenus cloud : en hausse de 25 % Revenus de la suite Cloud ERP : +33 % Backlog cloud total : 63,3 milliards d’euros (+43 %) Résultat net : 3,12 milliards d’euros Marge nette : 9,14 %
B4: Chiffre d’affaires annuel en France | C4: 848 millions d'Euros
B5: Effectif total | C5: 92000
B6: Effectif en France | C6: cf tableau ci-contre
B7: Nombre de clients actifs dans le monde | C7: SAP compte plus de 440 000 clients dans 180 pays à travers le monde
B8: Nombre de clients actifs en France | C8: SAP compte environ 1 577 entreprises clientes en France
B9: Principaux secteurs d'activité | C9: L’industrie Le Retail et le Fashion Les services Le secteur public La distribution La santé
A11: Informations générales sur la solution | B11: Nom de la solution ERP | C11: Sap Cloud Erp Pirvate
B12: Version actuelle | C12: La version actuelle de SAP S/4HANA Cloud, Private Edition est la 2023 Release, avec plusieurs Feature Pack Stacks (FPS) publiés au cours de l’année, dont FPS03 est l’un des plus récents SAP S/4HANA Cloud Private Edition suit un cycle de mise à jour annuel, avec des support packages intermédiaire
B13: Date de sortie de la version actuelle | C13: La dernière version de SAP S/4HANA Cloud, Private Edition est la 2023 FPS02 (Feature Pack Stack 02), sortie le 9 octobre 2024
A15: Hébergement et mise à jour | B15: Type d'hébergement | C15: Tous
B16: Fréquence moyenne de mise à jour majeure | C16: une fois par an
B17: Fréquence moyenne de mise à jour mineure | C17: SAP prévoit de publier trois Feature Pack Stacks (FPS) pour chaque version majeure, à raison d’un tous les six mois.

Sheet 1. Besoins fonctionnels 
A1: LISTE DES BESOINS FONCTIONNELS | E1: REPONSE | F1: COMPLEXITE | G1: ESTIMATION COUTS SUPP. | H1: COMPLEMENTS (conseillés)
A3: I. Données référentielles
A4: Habiltations | B4: Gestion multi-sociétés, multi-entités | C4: Mutualisation contrôlée des accès et données : « mono- tenant »​ | E4: YES. Couvert en standard (100%) | G4: =_xlfn.IFNA(VLOOKUP(F4,'Abaques besoins fonctionnels'!$B$3:$C$5,2,0)," ")
C5: Modèle d’habilitations hiérarchisé : par rôle, société, entité juridique, marque, etc.​ | E5: YES. Couvert en standard (100%) | G5: =_xlfn.IFNA(VLOOKUP(F5,'Abaques besoins fonctionnels'!$B$3:$C$5,2,0)," ")
C6: Pilotage centralisé des rôles et autorisations : interface d’administration unique, reporting ​ | E6: YES. Couvert en standard (100%) | G6: =_xlfn.IFNA(VLOOKUP(F6,'Abaques besoins fonctionnels'!$B$3:$C$5,2,0)," ")
A7: Réseaux et clients​ | B7: Gestion des réseaux de vente​ | C7: Prise en charge d’une arborescence réseau de vente (magasins, clients internes) multi- niveaux et multi- vues, en lien avec les systèmes POS | E7: YES. Couvert en standard (100%) | G7: =_xlfn.IFNA(VLOOKUP(F7,'Abaques besoins fonctionnels'!$B$3:$C$5,2,0)," ") | H7: Gestion de hiérarchies de sites et de clients en standard pour gérer différentes vues. Existence de vues TPV de la fiche article dédiées, au niveau client, pour stocker et diffuser les informations articles pour le POS
C8: Gestion d’une organisation FDV (interne / externe, transverse / exclusive ), dont territoires commerciaux | E8: YES. Couvert en standard (100%) | G8: =_xlfn.IFNA(VLOOKUP(F8,'Abaques besoins fonctionnels'!$B$3:$C$5,2,0)," ") | H8: Possibilité de gérer d'autres types de regroupements de sites pour modéliser un découpage territorial propre au client et à son organisation de vente
B9: Hiérarchie comptes clients et données essentielles | C9: Prise en charge d’une hiérarchie de comptes clients multi- niveaux et multi- vues, en lien avec la CRM | E9: YES. Couvert en standard (100%) | G9: =_xlfn.IFNA(VLOOKUP(F9,'Abaques besoins fonctionnels'!$B$3:$C$5,2,0)," ") | H9: SAP couvre le besoin en termes de client B2B. Par contre une segmentzation marketing type B2C est hors périmètre, couverte par des outils de CRM.
C10: Gestion des données essentielles aux transactions et allocations​ | E10: YES. Couvert en standard (100%) | G10: =_xlfn.IFNA(VLOOKUP(F10,'Abaques besoins fonctionnels'!$B$3:$C$5,2,0)," ")
C11: Contrôle de complétion et reporting sur fiches clients non conformes | E11: CUS. Couvert avec customization | G11: =_xlfn.IFNA(VLOOKUP(F11,'Abaques besoins fonctionnels'!$B$3:$C$5,2,0)," ") | H11: Développement de vues CDS suppélementaires requis
A12: Articles | B12: Types d’articles et assortiments​ | C12: Prise en charge de types d’articles multiples (prototypes, samples / CoVoy, etc.) et de paramètres spécifiques​ | E12: YES. Couvert en standard (100%) | G12: =_xlfn.IFNA(VLOOKUP(F12,'Abaques besoins fonctionnels'!$B$3:$C$5,2,0)," ") | H12: Prise en charge de types d'articles multiples (prototypes, samples / CoVoy, etc.) et de paramètres spécifiques. Support natif pour différents types d'articles et scénarios spécifiques via la gestion des catégories et statuts article.
C13: Gestion d’assortiments et critères multiples d’affectation aux magasins / à la hiérarchie magasins (en lien avec PLM et PIM + CRM)​ | E13: YES. Couvert en standard (100%) | G13: =_xlfn.IFNA(VLOOKUP(F13,'Abaques besoins fonctionnels'!$B$3:$C$5,2,0)," ") | H13: Gestion d'assortiments et critères multiples d'affectation aux magasins / à la hiérarchie magasins (en lien avec PLM et PIM + CRM), Gestion intégrée des assortiments avec multiples critères d'affectation via Retail Assortment Management (licence spécifique)
C14: Gestion de catalogues et critères multiples d’affectation aux comptes clients ​ | E14: YES. Couvert en standard (100%) | G14: =_xlfn.IFNA(VLOOKUP(F14,'Abaques besoins fonctionnels'!$B$3:$C$5,2,0)," ") | H14: Gestion de catalogues et critères multiples d'une affectation aux comptes clients, Attribution flexible des catalogues à des clients et magasins avec filtrage multi-critères intégré dans le Master Data.
B15: Variantes articles​ | C15: Prise en charge de variantes articles permettant d’affecter différentes valeurs d’attributs à une même référence (ex : même article tshirt en coton, valeur d’attribut « composition » différente)​ | E15: YES. Couvert en standard (100%) | G15: =_xlfn.IFNA(VLOOKUP(F15,'Abaques besoins fonctionnels'!$B$3:$C$5,2,0)," ") | H15: Prise en charge de variantes articles permettant d'affecter différentes valeurs d'uneattributs à une même référence. Gestion de variantes via des grilles article (matrice Style/Color/Size) et attributs extensibles.
C16: Prise en charge de variantes multiples d’un même article pour une même saison​ | E16: YES. Couvert en standard (100%) | G16: =_xlfn.IFNA(VLOOKUP(F16,'Abaques besoins fonctionnels'!$B$3:$C$5,2,0)," ") | H16: Prise en charge de variantes multiples d'un même article pour une même saison. Lien avec la saison/collection via la hiérarchie merchandising. Les variantes sont associées à des saisons.
C17: Gestion des niveaux « variante » (détaillé) et « référence » (« agrégé ») sur l’ensemble des flux, traitements et données (historiques, commandes et transactions, stocks…) et possibilité de définir le niveau optimum de traitement / gestion, selon les cas​ | E17: YES. Couvert en standard (100%) | G17: =_xlfn.IFNA(VLOOKUP(F17,'Abaques besoins fonctionnels'!$B$3:$C$5,2,0)," ") | H17: Gestion des niveaux " variante " (détaillé) et " référence " (" agrégé ")..., Gestion multi-niveaux (Style > Couleur > Taille) avec flux différenciés selon le niveau géré.
B18: Traçabilité des matières​ | C18: En lien avec la gestion des variantes articles et les nomenclatures (cf achats et réservations matières) :​ - Conserver dans les attributs, de chaque variante utilisée, les informations relatives à la matière : composition, origine, fournisseur, pays, etc.​ - Maintenir la traçabilité sur l’ensemble des flux, traitements et données (historiques, commandes et transactions, stocks…) et possibilité de définir le niveau optimum de traitement / gestion, selon les cas. | E18: YES. Couvert en standard (100%) | G18: =_xlfn.IFNA(VLOOKUP(F18,'Abaques besoins fonctionnels'!$B$3:$C$5,2,0)," ") | H18: Traçabilité des matières : composition, origine, fournisseur, etc.,Attributs matières liés à chaque variante et suivi dans toute la supply chain via les modules MM et SD.
B19: Hiérarchie articles et gestion MCT​ | C19: Prise en charge native d’une hiérarchie articles adaptée au secteur : catégories, familles, groupes… | E19: YES. Couvert en standard (100%) | G19: =_xlfn.IFNA(VLOOKUP(F19,'Abaques besoins fonctionnels'!$B$3:$C$5,2,0)," ") | H19: Prise en charge native d'une hiérarchie articles adaptée au secteur,"Classification hiérarchique personnalisable selon les logiques métier (familles, groupes, classes)."
C20: Prise en charge native d’articles Modèle- Coloris- Taille et des règles de gestion associées (dont références articles / SKU) | E20: YES. Couvert en standard (100%) | G20: =_xlfn.IFNA(VLOOKUP(F20,'Abaques besoins fonctionnels'!$B$3:$C$5,2,0)," ") | H20: Prise en charge native d'articles Modèle- Coloris- Taille et des règles de gestion associées. Support complet du modèle Style/Color/Size avec génération automatique de SKU.
C21: Possibilité de gérer plusieurs hiérarchies Produit​ | E21: YES. Couvert en standard (100%) | G21: =_xlfn.IFNA(VLOOKUP(F21,'Abaques besoins fonctionnels'!$B$3:$C$5,2,0)," ") | H21: Possibilité de gérer plusieurs hiérarchies Produit, Possibilité de créer et gérer plusieurs hiérarchies produit pour des usages différenciés.
B22: Poid des articles | C22: Prise en charge des poids des articles, dans leurs différentes variantes.​ | E22: YES. Couvert en standard (100%) | G22: =_xlfn.IFNA(VLOOKUP(F22,'Abaques besoins fonctionnels'!$B$3:$C$5,2,0)," ") | H22: Prise en charge des poids des articles, dans leurs différentes variantes,Chaque variante possède ses attributs de poids. Poids utilisés dans la logistique et le calcul des coûts.
B23: Articles de regroupements | C23: Prise en charge de types d’articles de regroupement (packs et assimilés, ex : X- t- shirts), à la vente et / ou en gestion sur les différentes étapes du flux​ | E23: YES. Couvert en standard (100%) | G23: =_xlfn.IFNA(VLOOKUP(F23,'Abaques besoins fonctionnels'!$B$3:$C$5,2,0)," ") | H23: Différents types de packs sont possible dépendant de leur comportement dans la chaine logistique et sont géré à travers des catégories d'articles
C24: Gestion de SKU / références spécifiques à ces articles de regroupement (ex : pack de X t- shirts)​ | E24: YES. Couvert en standard (100%) | G24: =_xlfn.IFNA(VLOOKUP(F24,'Abaques besoins fonctionnels'!$B$3:$C$5,2,0)," ") | H24: Gestion de SKU / références spécifiques à ces articles de regroupement.
C25: Conservation des SKU / références unitaires pour les articles regroupés (ex : chaque référence t- shirt entrant dans le pack)​ | E25: YES. Couvert en standard (100%) | G25: =_xlfn.IFNA(VLOOKUP(F25,'Abaques besoins fonctionnels'!$B$3:$C$5,2,0)," ") | H25: Conservation des SKU / références unitaires pour les articles regroupés"SKU composants visibles et gérés individuellement en stock, même dans les packs."
C26: Prise en charge d’attributs et de valeurs spécifiques aux articles de regroupement, dont spécifique (et règle de répartition du prix « packagé » sur les articles unitaires)​ | E26: YES. Couvert en standard (100%) | G26: =_xlfn.IFNA(VLOOKUP(F26,'Abaques besoins fonctionnels'!$B$3:$C$5,2,0)," ") | H26: Prise en charge d'attributs et de valeurs spécifiques aux articles de regroupement. Attributs spécifiques et règles de valorisation du prix packagé réparti selon clés paramétrables.
B27: Autres articles et prestations (upcharges)​ | C27: Prise en charge de prestations de service additionnelles et des différents modes de tarification / facturation associés​ | E27: YES. Couvert en standard (100%) | G27: =_xlfn.IFNA(VLOOKUP(F27,'Abaques besoins fonctionnels'!$B$3:$C$5,2,0)," ") | H27: Prise en charge de prestations de service additionnelles..., Fonctionnalités de service articles intégrées avec gestion tarifaire dédiée.
C28: Gestion de règles d’ajout manuel et automatique de prestations complémentaires, sous conditions / paramètres gérés dans l’ERP | E28: YES. Couvert en standard (100%) | G28: =_xlfn.IFNA(VLOOKUP(F28,'Abaques besoins fonctionnels'!$B$3:$C$5,2,0)," ") | H28: Gestion de règles d'ajout manuel et automatique de prestations complémentaires,"Définition de règles via des conditions (ex : canal, client, seuil) déclenchant ajout automatique."
C29: Définition des prestations / coûts considérés comme « entrée » ou « sortie » (coefficients de calcul du prix de revient).​ | E29: YES. Couvert en standard (100%) | G29: =_xlfn.IFNA(VLOOKUP(F29,'Abaques besoins fonctionnels'!$B$3:$C$5,2,0)," ") | H29: Définition des prestations / coûts considérés comme " entrée " ou " sortie " à travers les schémas de prix. Paramétrage comptable différenciant entrée/sortie selon type de service (ajouté ou détachable).
C30: Déclenchement automatique des évènements de facturation associés | E30: YES. Couvert en standard (100%) | G30: =_xlfn.IFNA(VLOOKUP(F30,'Abaques besoins fonctionnels'!$B$3:$C$5,2,0)," ") | H30: Déclenchement automatique des évènements de facturation associés (upcharges) en lien avec la facturation : événement de facturation déclenché automatiquement selon le paramétrage du flux.
B31: VAS (Value Added Services)​ | C31: Prise en charge de Services à Valeur Ajoutée​ | E31: YES. Couvert en standard (100%) | G31: =_xlfn.IFNA(VLOOKUP(F31,'Abaques besoins fonctionnels'!$B$3:$C$5,2,0)," ") | H31: Prise en charge de Services à Valeur Ajoutée,VAS intégrés comme objets article spécifiques avec règles d'ajout conditionnel.
C32: Gestion de règles d’ajout manuel et automatique de VAS, sous conditions / paramètres gérés dans l’ERP​ | E32: YES. Couvert en standard (100%) | G32: =_xlfn.IFNA(VLOOKUP(F32,'Abaques besoins fonctionnels'!$B$3:$C$5,2,0)," ") | H32: Gestion de règles d'ajout manuel et automatique de VAS,comme pour les upcharges, avec règles liées au client, canal, commande ou segment."
C33: Déclenchement automatique des évènements de facturation associés | E33: YES. Couvert en standard (100%) | G33: =_xlfn.IFNA(VLOOKUP(F33,'Abaques besoins fonctionnels'!$B$3:$C$5,2,0)," ") | H33: Déclenchement automatique des évènements de facturation associés (VAS),Evenements de facturation automatiquement générés si VAS déclenchés.
B34: Grilles de tailles​ | C34: Prise en charge de multiples types, dimensions et unités de taille, adaptées au secteur textile (bonnet, longueur de jambe, demi- pointure, etc). | E34: YES. Couvert en standard (100%) | G34: =_xlfn.IFNA(VLOOKUP(F34,'Abaques besoins fonctionnels'!$B$3:$C$5,2,0)," ") | H34: Prise en charge de multiples types, dimensions et unités de taille,"Grilles tailles multiples supportées (longueur de jambe, bonnet, pointure, etc.)."
C35: Gestion d’une taille principale (ex : taille 40) et de dimensions associées (ex : tour de taille, jambe, cheville, etc.) ​ | E35: YES. Couvert en standard (100%) | G35: =_xlfn.IFNA(VLOOKUP(F35,'Abaques besoins fonctionnels'!$B$3:$C$5,2,0)," ") | H35: Gestion d'uneune taille principale et de dimensions associées,Dimension principale gérée avec dimensions secondaires associées dans la grille article.
C36: Gestion d’index et de valeurs de tailles (ex : 1=XXS, 2=XS, 3=S…) associés aux différentes typologies articles​ | E36: YES. Couvert en standard (100%) | G36: =_xlfn.IFNA(VLOOKUP(F36,'Abaques besoins fonctionnels'!$B$3:$C$5,2,0)," ") | H36: Gestion d'un index et de valeurs de tailles associées aux articles,"Indexation des tailles et codification personnalisable (1=XS, 2=S...)."
C37: Possibilité de modifier les grilles de tailles, y compris l’ajout ou la suppression de tailles (sans création d’un nouvel article / SKU).​ | E37: YES. Couvert en standard (100%) | G37: =_xlfn.IFNA(VLOOKUP(F37,'Abaques besoins fonctionnels'!$B$3:$C$5,2,0)," ") | H37: Possibilité de modifier les grilles de tailles sans créer un nouvel article / SKU,Ajout/suppression de tailles sans recréer un article maitre ou un SKU.
C38: Gestion d’un ordre d’apparition des tailles dans une grille, indépendante de l’index (ex : si XXL = indice 2 = ordre d’apparition 6)​ | E38: YES. Couvert en standard (100%) | G38: =_xlfn.IFNA(VLOOKUP(F38,'Abaques besoins fonctionnels'!$B$3:$C$5,2,0)," ") | H38: Gestion d'uneun ordre d'apparition des tailles dans une grille,Possibilité de gérer ordre d' affichage différent de l'ordre indexé (ordre marché).
C39: Prise en charge de tables et règles de correspondance de tailles entre les différentes normes marchés / pays.​ | E39: YES. Couvert en standard (100%) | G39: =_xlfn.IFNA(VLOOKUP(F39,'Abaques besoins fonctionnels'!$B$3:$C$5,2,0)," ") | H39: Prise en charge de correspondance de tailles entre normes marchés / pays,Mapping entre normes (EU/US/UK/JP) via tables de conversion dans Retail Master.
B40: Gestion des données d’étiquetage | C40: Gestion des données d’étiquetage handtags : template / ID document, valeurs (prix, devises, tailles) et index.​ | E40: YES. Couvert en standard (100%) | G40: =_xlfn.IFNA(VLOOKUP(F40,'Abaques besoins fonctionnels'!$B$3:$C$5,2,0)," ") | H40: Gestion des données d'uneétiquetage handtags : template / ID document...,"Templates configurables avec données dynamiques (prix, tailles, devise) par canal."
C41: Règles multicritères (canal, client, commande, etc.) de sélection des tailles à afficher sur les étiquettes, parmi les tailles disponibles.​ | E41: YES. Couvert en standard (100%) | G41: =_xlfn.IFNA(VLOOKUP(F41,'Abaques besoins fonctionnels'!$B$3:$C$5,2,0)," ") | H41: Règles multicritères pour la sélection des tailles à afficher sur étiquette,Paramétrage de règles multicritères pour afficher la bonne taille selon contexte vente.
...

Sheet Abaques besoins fonctionnels
A1: Type de développement | B1: Niveau de complexité | C1: Total
A3: Enh / Exits / Badi | B3: Low | C3: 10
A4: Enh / Exits / Badi | B4: Medium | C4: 18
A5: Enh / Exits / Badi | B5: High | C5: 28

Sheet 2. Interfaces 
A1: DOMAINE | B1: APPLICATION | C1: ROLE | D1: PRINCIPALES DONNEES ENVOYEES PAR L'ERP | E1: PRINCIPALES DONNEES RECUES PAR L'ERP | F1: REPONSE SANS INTEGRATION SUITE | G1: REPONSE AVEC INTEGRATION SUITE | H1: ESTIMATION COUTS MISE EN ŒUVRE | I1: LIMITE DE VOLUME DE TRANSFERT O/N | J1: DETAIL DES LIMITES DE TRANSFERT | K1: COMMENTAIRE (facultatif) | L1: ESTIMATION COUTS MISE EN ŒUVRE (Numérique)
A2: Planification des achats | B2: OPTIMATE | C2: Calcule les budgets d'achats à partir des budgets de ventes Etablit les planning hebdomadaires d'achats | D2: - | E2: - Demandes d'achats (à la semaine) - par Modèle Coloris Taille - par client (Beaumanoir découpe ses commandes d'achat par canal et client) | F2: DEV. Interface spécifique à développer | G2: DEV. Interface spécifique à développer | H2: 44J | I2: NON | K2: 2 interfaces entrantes | L2: 44
A3: Développement des produits | B3: CENTRIX PLM | C3: Définit la liste des Articles et leurs données / attributs Gère les assortiments (segmentation client et magasins) | D3: - | E3: - Données articles détaillées : codes, désignations, attributs | F3: DEV. Interface spécifique à développer | G3: CUS. Connecteur spécifique existant | H3: 66J | I3: NON | K3: 3 interfaces entrantes , accélérateurs delaware pour SAP Intégration Suite | L3: 66
A4: Portail fournisseurs et partenaires | B4: SAP SNC | C4: Met à jour les commandes d'achat (saisie fournisseurs via portail) Transmet des données relatives aux commandes d'achat (messages transitaire, étiquettes au partenaire dédiée, etc.) | D4: - Données de commandes détaillées (à la ligne) - Références articles et données essentielles (pour étiquettes composition) - Données d'étiquettage retail (index et donnés tailles et prix) | E4: - Mise à jour de commandes d'achats | F4: DEV. Interface spécifique à développer | G4: DEV. Interface spécifique à développer | H4: 70J | I4: NON | K4: 3 interfaces sortantes 1 interface entrante | L4: 70
A5: Gestion d'entrepôts | B5: INCONSO WMS MANHATTAN WMS REFLEX WMS | C5: Pilote les opérations entrepôt (stocks, commandes) en lien avec l'ERP | D5: - Données articles détaillées - Données de commandes d'achat détaillées - Données de commandes de vente détaillées | E5: - Mouvements de stocks - Mise à jour statuts de commandes de vente - Mise à jour statuts de commandes d'achat | F5: DEV. Interface spécifique à développer | G5: DEV. Interface spécifique à développer | H5: 361J | I5: NON | K5: 9 interfaces sortantes 9 interfaces entrantes | L5: 361
A6: Calcul des optimums de stocks magasins | B6: SCOR-TEX | C6: Calcule les stocks magasin idéaux sur la base des données de ventes et de stocks Peut calculer des propositions de réapprovisionnement à partir des données de ventes et d'écoulement et des stocks | D6: - Données de stocks centraux, par Modèle Coloris Taille | E6: - Réception des optimum de stocks magasins calculés par SCOR-TEX, au niveau MCT / magasin | F6: DEV. Interface spécifique à développer | G6: DEV. Interface spécifique à développer | H6: 38J | I6: NON | K6: 1 interface entrante 1 interface sortante | L6: 38
A7: Gestion des points de vente (POS) | B7: CEGID Y2 | C7: Gère l'ensemble des opérations des magasins, dont émission des demandes de réassort, réception des commandes de réassort et stocks magasins au détail | D7: - Données articles détaillées - Données de prix détaillées - Données d'opérations promotionnelles - Données de commandes de vente détaillées (MEP et réassort) - Messages et annonces logistiques (livraisons, retours) | E7: - Ventes magasins (consolidées) - Valeurs des stocks magasins - Demandes de réassort | F7: DEV. Interface spécifique à développer | G7: DEV. Interface spécifique à développer | H7: 183J | I7: NON | K7: 6 interfaces sortantes 4 interfaces entrantes | L7: 183
A8: Gestion des points de vente (POS) | B8: UNIVERS RETAIL | C8: Gère l'ensemble des opérations des magasins, dont réception des commandes de réassort et stocks magasins au détail | D8: - Données articles détaillées - Données de prix détaillées - Données d'opérations promotionnelles - Données de commandes de vente détaillées (MEP et réassort) - Messages et annonces logistiques (livraisons, retours) | E8: - Ventes magasins (consolidées) - Valeurs des stocks magasins - Demandes de réassort | F8: DEV. Interface spécifique à développer | G8: DEV. Interface spécifique à développer | H8: 183J | I8: NON | K8: 6 interfaces sortantes 4 interfaces entrantes | L8: 183
A9: Relation client (CRM) | B9: ZOHO CRM | C9: Pilote la relation client et la passation des commandes wholesale et e-commerce (appuyé par Elastic Search) Publie les catalogues clients Gère certaines opérations promotionnelles | D9: - Organisation commerciale - Données articles détaillées - Données de prix détaillées (dont conditions de vente) - Données d'opérations promotionnelles - Données de commandes détaillées (B2B, e-commerce) - Messages et annonces logistiques (livraisons, retours) | E9: - Données clients essentielles (référentielles) - Détail des commandes de vente à créer - Détail des demandes de retours à traiter | F9: DEV. Interface spécifique à développer | G9: DEV. Interface spécifique à développer | H9: 178J | I9: NON | K9: 7 interfaces sortantes 3 interfaces entrantes | L9: 178
A10: Relation client (CRM) | B10: SALESFORCE CRM | C10: Pilote la relation client et la passation des commandes wholesale et e-commerce (appuyé par Elastic Search) Publie les catalogues clients Gère certaines opérations promotionnelles | D10: - Organisation commerciale - Données articles détaillées - Données de prix détaillées (dont conditions de vente) - Données d'opérations promotionnelles - Données de commandes détaillées (B2B, e-commerce) - Messages et annonces logistiques (livraisons, retours) | E10: - Données clients essentielles (référentielles) - Détail des commandes de vente à créer - Détail des demandes de retours à traiter | F10: DEV. Interface spécifique à développer | G10: STD. Connecteur standard existant | H10: 178J | I10: NON | K10: 7 interfaces sortantes 3 interfaces entrantes 'Package SAP Integration Suite pour Salesforce. | L10: 178
A11: Commissionnement | B11: SAP VISTEX | C11: Calcule les factures de commission (force de vente partenaire) | D11: - Organisation commerciale - Données clients essentielles (référentielles) - Données essentielles de commandes de vente (chiffre d'affaires et données de calcul) | E11: - Détail des "commandes de commissionnement" à régler (par partenaire FDV) | F11: STD. Connecteur standard existant | G11: STD. Connecteur standard existant | H11: 124J | I11: NON | K11: Connecteur standard de Vistex 5 flux sortantes et 2 entrants | L11: 124
A12: Finance et comptabilité | B12: SAP FICO | C12: Génère et enregistre les factures Assure la gestion financière et comptable | D12: - Données clients / tiers à facturer détaillées - Données spécifiques à la facturation : template à utiliser, mentions particulières, etc. - Données d'éditique : template complet, valeurs de champs - Conditions contractuelles et conditions de remise détaillées - Données de commandes de ventes détaillées (articles et prestations, prix, devise) | E12: - | F12: STD. Connecteur standard existant | G12: STD. Connecteur standard existant | H12: 80J | I12: NON | K12: Connexion RFC avec paramétrage d'IDOC standard. Vérifier si un DEV est à prévoir sur les données d'editique. 5 interfaces sortantes | L12: 80
L13: =SUM(L1:L12) -> 1505 | M13: Jours de développement des interfaces.
B14: * il s'agit ici de recenser les données essentielles et susceptibles de représenter la volumétrie la plus importante

Sheet 3. Architecture et sécurité
A1: LISTE DES CRITERES NON FONCTIONNELS | D1: REPONSE | E1: COMPLEMENTS
A2: Architecture | B2: Généralités | C2: Quels langages de programmation sont utilisés pour le développement de votre ERP? | D2: Cf compléments | E2: Le développement de SAP S/4HANA repose sur un ensemble de langages de programmation et de technologies adaptés à différents niveaux de la plateforme (backend, frontend, intégration, extensions). Voici les principaux : 1. ABAP (Advanced Business Application Programming) Langage principal pour le développement backend dans SAP S/4HANA Utilisé pour : La logique métier Les rapports Les extensions personnalisées (via ABAP RESTful Application Programming Model) ABAP est exécuté sur la SAP NetWeaver Application Server ou SAP BTP ABAP Environment 2. JavaScript / TypeScript Utilisés côté frontend, notamment avec SAP Fiori (interface utilisateur moderne) Développement d’applications avec SAPUI5 (framework basé sur JavaScript) TypeScript est souvent utilisé dans les projets Fiori Elements ou CAP (Cloud Application Programming) 3. Java Utilisé dans certains services de la SAP Business Technology Platform (BTP) Présent dans les microservices, les intégrations, ou les extensions cloud 4. SQLScript Langage de requête utilisé dans SAP HANA pour écrire des procédures stockées et des vues calculées Optimisé pour le traitement in-memory 5. Node.js / Python (dans certains cas) Utilisés pour des extensions cloud, des API, ou des intégrations personnalisées via SAP BTP Pas natifs à SAP S/4HANA, mais compatibles via des environnements comme SAP Kyma ou SAP Cloud Foundry 🔧 Environnement de développement Eclipse avec ABAP Development Tools (ADT) pour le backend SAP Business Application Studio ou Visual Studio Code pour le frontend et les extensions cloud
C3: Quelles sont les bases de données actuellement supportées par votre ERP? | D3: HANA | E3: SAP S/4HANA est conçu pour fonctionner exclusivement avec la base de données SAP HANA, qui est une base de données en mémoire (In-Memory) développée par SAP.
B4: Modularité | C4: Votre solution permet-elle des développements spécifiques ? Si oui, dans quel langage ? | D4: OUI | E4: Oui, SAP S/4HANA permet des développements spécifiques, appelés aussi extensions ou custom developments, pour répondre aux besoins métiers particuliers d’une entreprise. 🧩 Types de développements spécifiques possibles 1. Développements dans le core (In-App) Réalisés directement dans le système SAP S/4HANA Utilisent le langage ABAP (Advanced Business Application Programming) Exemples : Ajout de champs personnalisés Création de rapports spécifiques Développement de modules fonctionnels sur mesure 2. Développements en dehors du core (Side-by-Side) Réalisés sur la SAP Business Technology Platform (SAP BTP) Permettent de ne pas impacter le cœur standard de S/4HANA Utilisent des langages modernes comme : JavaScript / TypeScript (via SAP Fiori / SAPUI5) Java (pour les microservices) Node.js ou Python (dans des environnements comme SAP Kyma ou Cloud Foundry) SQLScript (pour les traitements dans SAP HANA) 🛠️ Outils de développement Eclipse avec ABAP Development Tools (ADT) : pour le backend ABAP SAP Business Application Studio : pour les applications Fiori, CAP, extensions cloud SAP Web IDE (ancien, en voie de remplacement)
C5: Les domaines fonctionnels suivants sont-ils couverts par le socle principal, ou des modules / solutions annexes ?
C6: - Planning (amont) | D6: SOC. Socle central | E6: La fonctionnalité de planning amont est bien intégrée dans SAP S/4HANA, notamment via les modules PP/DS (Production Planning and Detailed Scheduling) et SAP Integrated Business Planning (IBP). 🧠 1. Planning amont dans SAP S/4HANA (PP/DS intégré) Depuis les dernières versions, PP/DS est intégré nativement dans le cœur de SAP S/4HANA, ce qui permet : De planifier la production en amont, en tenant compte des contraintes de capacité, de ressources et de disponibilité des composants. D’utiliser des outils comme : Le detailed scheduling planning board (planification graphique). Le product planning table. Des heuristiques standard et des optimisations automatiques pour ajuster les séquences de production 1. 🔄 2. Synchronisation avec la planification globale SAP S/4HANA permet une planification intégrée entre les achats, la production, les ventes et la logistique. Le planning amont est synchronisé avec : Les prévisions de demande. Les contraintes de production. Les engagements clients (ATP – Available to Promise). 🌐 3. Extension avec SAP IBP (optionnel) Pour des scénarios plus complexes ou multi-sites : SAP Integrated Business Planning (IBP) peut être utilisé en complément. Il permet une planification stratégique et tactique (S&OP, planification de la demande, planification des approvisionnements). Intégration fluide avec S/4HANA via des connecteurs standards 2. ✅ En résumé : SAP S/4HANA intègre nativement des fonctionnalités de planning amont, via PP/DS, avec des capacités avancées de planification, d’optimisation et de synchronisation des processus industriels.
C7: - Gestion des achats | D7: SOC. Socle central | E7: a gestion des achats est entièrement intégrée dans SAP S/4HANA. Elle fait partie du module central de gestion des approvisionnements, appelé SAP S/4HANA Sourcing and Procurement. 🛒 Fonctionnalités principales de la gestion des achats dans SAP S/4HANA ✅ 1. Gestion des fournisseurs Création et gestion des fiches fournisseurs. Évaluation des performances fournisseurs. Intégration avec des portails fournisseurs (ex. : SAP Ariba). ✅ 2. Demandes et commandes d’achat Création de demandes d’achat (DA) manuelles ou automatiques. Transformation en commandes d’achat. Suivi des confirmations, livraisons et factures. ✅ 3. Contrats et accords-cadres Gestion des contrats d’achat à long terme. Suivi des consommations et des engagements. ✅ 4. Intégration logistique et financière Intégration avec : La gestion des stocks (réceptions, mouvements). La comptabilité fournisseurs (facturation, paiements). Le contrôle budgétaire. ✅ 5. Analyse et pilotage Tableaux de bord Fiori pour : Suivre les dépenses. Identifier les fournisseurs critiques. Optimiser les délais et les coûts. 🧠 Extensions possibles SAP Ariba : pour la gestion collaborative des achats (sourcing, appels d’offres, catalogues). SAP Fieldglass : pour les achats de prestations externes. SAP Central Procurement : pour centraliser les achats dans des environnements multi-ERP.
C8: - Portail fournisseur (avec workflow intégré) | D8: MOD. Module complémentaire (MDD partagé avec socle principal) | E8: Le portail fournisseur n’est pas directement intégré au cœur de SAP S/4HANA, mais il peut être étroitement connecté à l’ERP via des solutions complémentaires de l’écosystème SAP, notamment : 🔗 1. SAP Ariba – Portail fournisseur principal SAP Ariba est la solution dédiée de SAP pour la gestion des fournisseurs, des appels d’offres, des contrats et des commandes. Elle est intégrée nativement avec SAP S/4HANA, notamment via des connecteurs standards. Elle permet aux fournisseurs de : Répondre à des appels d’offres. Gérer les commandes et les factures. Suivre les paiements et les litiges. 🧩 2. Intégration avec SAP S/4HANA Dans SAP S/4HANA, les modules Achats (MM) et Gestion des fournisseurs permettent de gérer les données fournisseurs, les commandes, les réceptions et les paiements. Le portail fournisseur (via Ariba ou autre) s’appuie sur ces modules pour afficher les données en temps réel. L’intégration est facilitée par des API standardisées et des interfaces Fiori. 🛠️ 3. Alternatives personnalisées Il est aussi possible de créer un portail fournisseur personnalisé directement connecté à SAP S/4HANA via : SAP Fiori apps. SAP Business Technology Platform (BTP). SAP Integration Suite. ✅ En résumé : Le portail fournisseur n’est pas dans le cœur natif de SAP S/4HANA, mais il est pleinement intégré via SAP Ariba ou des solutions personnalisées, avec une synchronisation en temps réel des données ERP.
C9: - Gestion des stocks | D9: SOC. Socle central | E9: Oui, la gestion des stocks est bien intégrée dans SAP S/4HANA. Elle fait partie du module SAP Materials Management (MM), plus précisément dans la composante Inventory Management (IM). 📦 Fonctionnalités principales de la gestion des stocks dans SAP S/4HANA ✅ 1. Suivi des mouvements de stock Entrées et sorties de marchandises (réceptions, livraisons, transferts internes). Mouvements automatiques liés aux commandes d’achat, de production ou de vente. Gestion des types de mouvements (101, 201, 301, etc.). ✅ 2. Gestion multi-emplacements Suivi des stocks par : Site (plant), Magasin (storage location), Lot, numéro de série, unité de manutention. ✅ 3. Inventaire physique Planification et exécution des comptages d’inventaire. Ajustements automatiques des écarts. Historique et traçabilité des écarts. ✅ 4. Intégration avec d'autres modules Achats : réception de marchandises. Ventes : sorties de stock. Production : consommation de composants. Finance : valorisation des stocks en temps réel. ✅ 5. Gestion des stocks spéciaux Stocks consignés, en transit, bloqués, en sous-traitance, etc. 🧠 Extensions possibles SAP Extended Warehouse Management (EWM) : pour une gestion avancée des entrepôts. SAP Fiori apps : pour une gestion moderne et mobile des stocks
C10: - Gestion des ventes | D10: SOC. Socle central | E10: La gestion des ventes est intégrée dans SAP S/4HANA, via le module Sales and Distribution (SD), qui fait partie du cœur fonctionnel de l’ERP. 🛍️ Fonctionnalités principales de la gestion des ventes dans SAP S/4HANA ✅ 1. Gestion du cycle de vente complet Création de devis, commandes clients, livraisons, factures. Suivi des conditions commerciales (remises, frais, taxes). Gestion des retours et avoirs. ✅ 2. Intégration logistique et financière Coordination avec : La gestion des stocks pour les livraisons. La comptabilité clients pour la facturation et les paiements. La planification de la production pour les produits fabriqués à la commande. ✅ 3. Disponibilité produit et promesse client (ATP) Fonction Available-to-Promise (ATP) pour vérifier la disponibilité des produits en temps réel. Planification des livraisons selon les capacités logistiques. ✅ 4. Analyse des ventes Tableaux de bord Fiori pour : Suivre les performances commerciales. Analyser les marges, volumes, délais. Identifier les clients et produits stratégiques. ✅ 5. Gestion des contrats et abonnements Contrats-cadres, commandes périodiques. Intégration possible avec SAP Subscription Billing pour les modèles récurrents. 🧠 Extensions possibles SAP Customer Experience (CX) : pour CRM, e-commerce, marketing. SAP CPQ : pour la configuration de produits complexes. SAP Commerce Cloud : pour les ventes en ligne.
C11: - Transport | D11: SOC. Socle central | E11: La gestion du transport est bien prise en charge dans SAP S/4HANA, mais elle dépend du niveau de complexité requis et du module utilisé. 🚚 1. Gestion de base du transport dans SAP S/4HANA (core ERP) SAP S/4HANA intègre des fonctionnalités de logistique de transport dans les modules suivants : Sales and Distribution (SD) : pour la planification des livraisons, la création de documents de transport, la gestion des expéditions. Materials Management (MM) : pour les mouvements de marchandises liés aux achats et transferts. Warehouse Management (WM) ou Stock Room Management : pour la coordination des mouvements internes. Ces fonctions couvrent : La création de livraisons. L’affectation de transporteurs. Le suivi des expéditions. La gestion des coûts de transport (via conditions de prix). 🚛 2. SAP Transportation Management (SAP TM) Pour des besoins plus avancés, SAP propose SAP Transportation Management, qui peut être : Intégré nativement dans SAP S/4HANA (Embedded TM). Ou utilisé comme solution autonome (side-car). SAP TM permet : La planification optimisée des transports (multi-modal, multi-étapes). La gestion des transporteurs et des contrats. Le suivi en temps réel des expéditions. La facturation du fret et la gestion des litiges. 🧩 3. Intégration avec d'autres modules SAP TM s’intègre avec : SAP EWM (gestion d’entrepôt avancée). SAP GTS (gestion du commerce international). SAP Event Management (suivi des événements logistiques). ✅ En résumé : SAP S/4HANA prend en charge la gestion du transport, soit via des fonctions de base intégrées, soit via SAP Transportation Management pour des processus logistiques complexes.
C12: - Portail / communication prestataires transport (avec workflow intégré) | D12: MOD. Module complémentaire (MDD partagé avec socle principal) | E12: Oui, SAP S/4HANA peut couvrir la communication avec les prestataires de transport via un portail, avec des workflows intégrés, mais cela dépend de la solution utilisée et de son niveau d’intégration. 🚚 1. SAP S/4HANA avec SAP Transportation Management (SAP TM) SAP TM, intégré à SAP S/4HANA (en version Embedded TM), permet : La gestion complète des opérations de transport (planification, exécution, suivi). L’intégration avec les prestataires de transport via des interfaces EDI/API. La gestion des workflows pour l’approbation, la validation des coûts de transport, ou la gestion des litiges. 🌐 2. Portail fournisseur / transporteur (via SAP Business Network ou Ariba Network) SAP propose des portails collaboratifs pour les fournisseurs et transporteurs : SAP Business Network for Logistics (anciennement Ariba Network Logistics). Permet aux transporteurs de : Recevoir des ordres de transport. Confirmer les livraisons. Suivre les expéditions. Gérer les documents (CMR, factures, etc.). Ces portails sont connectés à SAP S/4HANA et peuvent déclencher des workflows intégrés (ex. : validation de réception, approbation de facture). 🔄 3. Workflows intégrés dans SAP S/4HANA SAP S/4HANA propose des workflows flexibles (via Fiori) pour : La gestion des commandes de transport. L’approbation des coûts logistiques. La validation des prestations de transport. Ces workflows peuvent être personnalisés et transportés entre environnements (DEV → QAS → PROD) via l’outil Adaptation Transport Organizer (ATO) 1. ✅ En résumé : SAP S/4HANA permet la gestion des prestataires de transport via un portail connecté, avec des workflows intégrés, notamment grâce à SAP TM et SAP Business Network for Logistics
C13: - ADV | D13: SOC. Socle central | E13: Oui, SAP peut tout à fait gérer l’ADV (Administration Des Ventes). Dans SAP, cette fonction est généralement couverte par le module SD (Sales and Distribution). Voici ce que le module SD permet de gérer pour l’ADV : 📦 Fonctions principales de l’ADV dans SAP SD : Gestion des devis et commandes clients : création, modification, suivi. Disponibilité des produits (ATP) : vérification des stocks en temps réel. Livraisons : préparation, expédition, gestion des bons de livraison. Facturation : génération automatique des factures à partir des livraisons. Suivi des paiements : en lien avec le module FI (Finance). Gestion des retours : retours produits, avoirs, etc. Reporting : tableaux de bord, analyses des ventes, délais, etc. 🔗 Intégration avec d'autres modules : MM (Materials Management) : pour la gestion des stocks. FI (Financial Accounting) : pour la facturation et le suivi des paiements. CO (Contrôle de gestion) : pour l’analyse de la rentabilité. CRM : pour la gestion de la relation client
A14: Sécurité et conformité | B14: Sécurité | C14: La localisation des serveurs est elle en France ? | D14: OUI | E14: Dépend de l'hyperscaler
C15: Possibilité de gérer des accès basés sur les rôles (Role-Based Access Control) | D15: OUI | E15: Oui, SAP S/4HANA prend en charge la gestion des accès basée sur les rôles, via un mécanisme appelé Role-Based Access Control (RBAC). C’est un pilier fondamental de la sécurité dans les environnements SAP. 🔐 Fonctionnement du RBAC dans SAP S/4HANA 1. Objets de sécurité clés Rôles (Roles) : regroupent des autorisations liées à des tâches ou fonctions spécifiques (ex. : comptable, acheteur, RH) Profils d’autorisations (Authorization Profiles) : définissent les droits d’accès à des objets SAP (transactions, vues, champs) Utilisateurs (Users) : se voient attribuer un ou plusieurs rôles 2. Types de rôles Rôles SAP standard : fournis par SAP pour les fonctions classiques (FI, MM, SD, etc.) Rôles personnalisés : créés par les administrateurs pour répondre aux besoins spécifiques de l’entreprise 3. Outils utilisés PFCG (Profile Generator) : outil principal pour créer et gérer les rôles et autorisations SU01 : gestion des utilisateurs SUIM : rapports sur les autorisations SAP Fiori Launchpad : permet de gérer les accès aux applications Fiori via des catalogues et groupes liés aux rôles ✅ Exemples d’usage Un responsable achats peut avoir accès uniquement aux transactions de commande (ME21N, ME22N) Un utilisateur Fiori peut voir uniquement les tuiles correspondant à ses rôles (ex. : "Créer une commande", "Consulter les fournisseurs")
C16: Possibilité de gérer le MFA (Multi-Factor Authentication) | D16: OUI | E16: Oui, SAP S/4HANA prend en charge l’authentification multifacteur (MFA), notamment dans les environnements cloud et hybrides, via des intégrations avec des solutions d’identité et de sécurité. 🔐 Fonctionnalités MFA dans SAP S/4HANA ✅ 1. Intégration avec SAP Identity Authentication Service (IAS) SAP IAS permet de configurer : MFA native (via application mobile, SMS, email, etc.) Authentification unique (SSO) avec MFA en amont Compatible avec SAP S/4HANA Cloud et SAP Fiori Launchpad ✅ 2. Intégration avec des fournisseurs tiers (IdP) SAP peut être intégré avec des solutions comme : Microsoft Entra ID (ex-Azure AD) Okta Ping Identity Google Workspace Ces fournisseurs peuvent imposer une MFA centralisée pour tous les accès SAP ✅ 3. Support via SAP Business Technology Platform (BTP) Pour les extensions ou applications connectées à S/4HANA via BTP, la MFA peut être activée au niveau de la gestion des identités cloud 🛠️ Exemples de méthodes MFA supportées Application mobile (TOTP) SMS ou email avec code à usage unique Clé de sécurité (FIDO2, YubiKey) Authentification biométrique (via IdP)
C17: Le système permet-il de gérer l’approbation des demandes d’accès (workflows d’approbation pour la création ou modification de rôles) ? | D17: OUI | E17: Oui, SAP permet de gérer les workflows d’approbation pour les demandes d’accès, y compris la création ou la modification de rôles, via plusieurs modules et outils intégrés : 1. SAP GRC Access Control Le module SAP GRC (Governance, Risk, and Compliance), en particulier Access Control, est conçu pour : Gérer les demandes d’accès utilisateurs. Définir des workflows d’approbation personnalisés. Automatiser les contrôles de séparation des tâches (SoD). Suivre et auditer les modifications de rôles et d’autorisations 1. 2. Workflows d’approbation dans SAP SAP propose des outils pour créer et modifier des procédures d’approbation : Utilisation d’un éditeur graphique pour concevoir des workflows complexes (approbateurs en série ou parallèles). Possibilité de définir des approbateurs ou réviseurs directement dans les tâches. Intégration avec des règles de gestion pour déclencher des approbations conditionnelles (ex. : selon le niveau de risque ou le type de rôle demandé) 2. 3. SAP Business Technology Platform (BTP) – Workflow Management Pour des besoins plus avancés ou personnalisés, SAP BTP permet de : Créer des workflows entièrement digitalisés. Intégrer des règles métiers complexes. Suivre l’état des demandes en temps réel
C18: Des mécanismes existent-ils pour revoir et actualiser régulièrement les autorisations d’accès ? | D18: OUI | E18: Voici les principaux mécanismes : 🔁 1. Revue des accès (Access Review) via SAP GRC Access Control Le module Access Risk Analysis (ARA) et Access Request Management (ARM) de SAP GRC permet de : Planifier des campagnes de revue des accès (périodiques ou ad hoc). Impliquer les managers ou propriétaires d’applications pour valider ou révoquer les accès. Générer des rapports d’audit sur les décisions prises. Automatiser les rappels et escalades en cas de non-réponse. 🧩 2. Segregation of Duties (SoD) et analyse des risques SAP GRC permet aussi de : Détecter les conflits d’autorisations (SoD). Proposer des mesures correctives ou des compensations. Mettre à jour les rôles pour éviter les risques futurs. 📅 3. Expiration automatique des autorisations Il est possible de configurer : Des dates d’expiration pour certains rôles ou accès temporaires. Des workflows de renouvellement si l’accès est encore nécessaire. 🛠️ 4. SAP Identity Management (IdM) SAP IdM permet : Une gestion centralisée du cycle de vie des identités. Des revues périodiques automatisées des rôles et autorisations. L’intégration avec des systèmes externes pour synchroniser les accès
C19: Possibilité de chiffrement des données critiques | D19: OUI | E19: Oui, SAP propose plusieurs mécanismes de chiffrement pour protéger les données critiques, que ce soit au repos, en transit ou dans les bases de données. Voici un aperçu des principales options disponibles : 🔐 1. Chiffrement des données au repos (Data at Rest) SAP prend en charge : SAP NetWeaver Secure Store and Forward (SSF) : pour chiffrer les fichiers sensibles. SAP HANA Native Encryption : Chiffrement des volumes de données et de journaux avec AES-256. Gestion des clés via SAP HANA Secure Store ou SAP Data Custodian. SAP ASE (Adaptive Server Enterprise) et SAP MaxDB offrent également des options de chiffrement natif. 🔄 2. Chiffrement des données en transit (Data in Transit) Utilisation de TLS/SSL pour sécuriser les communications entre : Clients SAP GUI et serveurs SAP. SAP Gateway, SAP Web Dispatcher, SAP Fiori, etc. Prise en charge de SAML 2.0, OAuth 2.0, et OpenID Connect pour l’authentification sécurisée. 🧩 3. SAP Data Custodian Un service cloud de SAP pour : Gérer les clés de chiffrement (Key Management Service). Appliquer des politiques de souveraineté des données. Fournir une traçabilité complète des accès et des opérations sur les données. 🛡️ 4. Intégration avec des solutions tierces SAP peut s’intégrer avec : HSM (Hardware Security Modules) pour la gestion sécurisée des clés. Solutions de chiffrement d’entreprise comme Thales, Vormetric, ou Microsoft Azure Key Vault.
C20: Possibilité de duplication des données | D20: OUI | E20: Oui, SAP permet la duplication des données, mais cela dépend du contexte fonctionnel et des outils utilisés. Voici les principales options disponibles : 📄 1. Duplication de données dans SAP ERP / S/4HANA SAP permet de dupliquer des objets métiers (clients, fournisseurs, articles, etc.) via : Fonctions de copie standard dans les transactions (ex. : copier une fiche article ou un rôle). LTMC (Legacy Transfer Migration Cockpit) ou SAP Data Services pour migrer ou dupliquer des ensembles de données. BDC (Batch Data Communication) ou LSMW (Legacy System Migration Workbench) pour automatiser la duplication de données en masse. 🧰 2. SAP Data Intelligence / SAP BTP Pour des scénarios plus complexes : SAP Data Intelligence permet de créer des pipelines de duplication, transformation et transfert de données entre systèmes SAP et non-SAP. SAP BTP (Business Technology Platform) permet de répliquer des données via des services comme SAP HANA Smart Data Integration ou Smart Data Access. 🔄 3. SAP Landscape Transformation (SLT) SLT permet : La réplication en temps réel de données entre systèmes SAP (ou vers des bases HANA). La duplication de tables entières ou de sous-ensembles filtrés. L’intégration avec des outils d’analyse ou de reporting. ☁️ 4. SAP Cloud Integration / CPI Dans un environnement cloud, SAP Cloud Platform Integration permet : La duplication ou synchronisation de données entre applications cloud (ex. : SAP SuccessFactors, Ariba, etc.). L’orchestration de flux de données avec transformation à la volée.
C21: Le système conserve-t-il un journal des accès utilisateur (logs de connexion et actions critiques) ? | D21: OUI | E21: Oui, SAP conserve un journal des accès utilisateur, y compris les connexions et les actions critiques, grâce à plusieurs mécanismes intégrés. Voici les principaux composants : 📘 1. Security Audit Log (SAL) Le Security Audit Log est l’outil principal pour tracer : Les connexions et déconnexions des utilisateurs. Les échecs d’authentification. Les modifications critiques (rôles, profils, mots de passe, etc.). Les accès aux transactions sensibles. 🔧 Il est configurable pour : Définir les événements à tracer. Choisir les utilisateurs ou groupes à surveiller. Exporter les logs pour audit ou analyse. 🧾 2. Change Documents (CDHDR/CDPOS) SAP enregistre les modifications de données (clients, fournisseurs, rôles, etc.) dans des tables de documents de modification, notamment : CDHDR : en-tête du changement (qui, quand, quoi). CDPOS : détails du changement (ancienne et nouvelle valeur). 🧠 3. SAP GRC Audit Management Pour les environnements réglementés, SAP GRC permet : De centraliser les logs d’audit. De générer des rapports sur les accès et les actions critiques. D’automatiser les alertes en cas d’activité suspecte. ☁️ 4. SAP Cloud Identity Services & SAP BTP Audit Logs Dans les environnements cloud : SAP Cloud Identity Authentication trace les connexions, tentatives échouées, MFA, etc. SAP BTP fournit des Audit Logs pour toutes les applications et services utilisés
