Workbook
Name ActiveCallVolumeScenarioIndex: iControl!$I$14
Name ActiveCostScenarioIndex: iControl!$I$24
Name cstArea: SysConfig!$G$40
Name cstConstantUnit: SysConfig!$G$37
Name cstDaysInWk: SysConfig!$G$30
Name cstFlag: SysConfig!$G$46
Name cstFTE: SysConfig!$G$41
Name cstHours: SysConfig!$G$45
Name cstMil: SysConfig!$G$29
Name cstMonthsInQtr: SysConfig!$G$32
Name cstMonthsInYr: SysConfig!$G$33
Name cstNominalUnit: SysConfig!$G$38
Name cstNum: SysConfig!$G$42
Name cstPercent: SysConfig!$G$43
Name cstProjectName: SysConfig!$G$12
Name cstProtectiveMarking: SysConfig!$G$18
Name cstRealUnit: SysConfig!$G$39
Name cstThou: SysConfig!$G$28
Name cstWeeksInYr: SysConfig!$G$31
Name cstYears: SysConfig!$G$44
Name eTol: SysConfig!$G$50
Name Heading1: MAX(cCosts!A$1:A1048576)+1
Name Heading1: MAX(cFactors!A$1:A1048576)+1
Name Heading1: MAX(cOutputs!A$1:A1048576)+1
Name Heading1: MAX(cVolumetrics!A$1:A1048576)+1
Name Heading1: MAX(iControl!A$1:A1048576)+1
Name Heading1: MAX(iIndices!A$1:A1048576)+1
Name Heading1: MAX(Introduction!A$1:A1048576)+1
Name Heading1: MAX(iOptions!A$1:A1048576)+1
Name Heading1: MAX(oDashboard!A$1:A1048576)+1
Name Heading1: MAX(oFinancials!A$1:A1048576)+1
Name Heading1: MAX(SysConfig!A$1:A1048576)+1
Name Heading1: MAX(SysTime!A$1:A1048576)+1
Name Heading2: MAX(cCosts!XFD$1:XFD1)&"."&COUNTIFS(cCosts!A$1:A1048576,MAX(cCosts!XFD$1:XFD1)&".*")+1
Name Heading2: MAX(cFactors!XFD$1:XFD1)&"."&COUNTIFS(cFactors!A$1:A1048576,MAX(cFactors!XFD$1:XFD1)&".*")+1
Name Heading2: MAX(cOutputs!XFD$1:XFD1)&"."&COUNTIFS(cOutputs!A$1:A1048576,MAX(cOutputs!XFD$1:XFD1)&".*")+1
Name Heading2: MAX(cVolumetrics!XFD$1:XFD1)&"."&COUNTIFS(cVolumetrics!A$1:A1048576,MAX(cVolumetrics!XFD$1:XFD1)&".*")+1
Name Heading2: MAX(iControl!XFD$1:XFD1)&"."&COUNTIFS(iControl!A$1:A1048576,MAX(iControl!XFD$1:XFD1)&".*")+1
Name Heading2: MAX(iIndices!XFD$1:XFD1)&"."&COUNTIFS(iIndices!A$1:A1048576,MAX(iIndices!XFD$1:XFD1)&".*")+1
Name Heading2: MAX(Introduction!XFD$1:XFD1)&"."&COUNTIFS(Introduction!A$1:A1048576,MAX(Introduction!XFD$1:XFD1)&".*")+1
Name Heading2: MAX(iOptions!XFD$1:XFD1)&"."&COUNTIFS(iOptions!A$1:A1048576,MAX(iOptions!XFD$1:XFD1)&".*")+1
Name Heading2: MAX(oDashboard!XFD$1:XFD1)&"."&COUNTIFS(oDashboard!A$1:A1048576,MAX(oDashboard!XFD$1:XFD1)&".*")+1
Name Heading2: MAX(oFinancials!XFD$1:XFD1)&"."&COUNTIFS(oFinancials!A$1:A1048576,MAX(oFinancials!XFD$1:XFD1)&".*")+1
Name Heading2: MAX(SysConfig!XFD$1:XFD1)&"."&COUNTIFS(SysConfig!A$1:A1048576,MAX(SysConfig!XFD$1:XFD1)&".*")+1
Name Heading2: MAX(SysTime!XFD$1:XFD1)&"."&COUNTIFS(SysTime!A$1:A1048576,MAX(SysTime!XFD$1:XFD1)&".*")+1
Name lstInflationRates: iIndices!$F$16:$F$20
Name lstScenariosCallVolume: SysConfig!$F$95:$F$97
Name lstScenariosCost: SysConfig!$F$101:$F$103
Name rngBoA: #REF!
Name rngChangeLog: #REF!
Name rngContents: Contents!$E$12:$I$25
Name rngNamedRanges: SysConfig!$F$56:$H$89
Name rngNewChange: #REF!
Name sysChk: Contents!$H$27
Name sysChkWord: SysConfig!$G$52
Name sysWarn: Contents!$I$27

Sheet Introduction
C1: THIS CASE STUDY MODEL IS FOR ILLUSTRATIVE PURPOSES
C2: =cstProjectName -> Should Cost Modelling Case Study - Illustrative SCM
C3: =MID(CELL("filename",A1),FIND("]",CELL("filename",A1))+1,256)&" Sheet" -> Introduction Sheet
C4: =IF(ISBLANK(cstProtectiveMarking),"",cstProtectiveMarking) -> Not Protectively Marked
C5: =HYPERLINK("#'Contents'!A1",sysChkWord) -> All Checks OK
C6: =HYPERLINK("#'Contents'!A1","Click for Contents") -> Click for Contents
C10: Foreward
C65: HMT Aqua Book
C66: HM Treasury’s Macpherson report
C67: Green Book
C68: SCM Guidance Note
C69: SCM Development Guidance
C70: SCM Technical Build Guidance
C71: SCM Templates & Tools
B73: END OF WORKSHEET - INSERT ROWS ABOVE

Sheet Contents
C1: THIS CASE STUDY MODEL IS FOR ILLUSTRATIVE PURPOSES
C2: =cstProjectName -> Should Cost Modelling Case Study - Illustrative SCM
C3: =MID(CELL("filename",A1),FIND("]",CELL("filename",A1))+1,256)&" Sheet" -> Contents Sheet
C4: =IF(ISBLANK(cstProtectiveMarking),"",cstProtectiveMarking) -> Not Protectively Marked
C5: =HYPERLINK("#'Contents'!A1",sysChkWord) -> All Checks OK
A8: =SUM(A9:A54) -> 0 | B8: =SUM(B9:B54) -> 0
D10: Contents
E12: Worksheet | F12: Link | G12: Sheet Description | H12: Errors | I12: Warnings
E13: Introduction | F13: Link | G13: Introduction to this this case study
E14: iControl | F14: Link | G14: Scenario selection set up sheet | H14: =iControl!A8 -> 0 | I14: =iControl!B8 -> 0
E15: iOptions | F15: Link | G15: General inputs sheet | H15: =iOptions!A8 -> 0 | I15: =iOptions!B8 -> 0
E16: iIndices | F16: Link | G16: Input sheet for indices | H16: =iIndices!A8 -> 0 | I16: =iIndices!B8 -> 0
E17: cFactors | F17: Link | G17: Calculation sheet for indexation calculations | H17: =cFactors!A8 -> 0 | I17: =cFactors!B8 -> 0
E18: cVolumetrics | F18: Link | G18: Calculation sheet for volumetrics | H18: =cVolumetrics!A8 -> 0 | I18: =cVolumetrics!B8 -> 0
E19: cCosts | F19: Link | G19: Calculation sheet for costs | H19: =cCosts!A8 -> 0 | I19: =cCosts!B8 -> 0
E20: cOutputs | F20: Link | G20: Calculation sheet for outputs | H20: =cOutputs!A8 -> 0 | I20: =cOutputs!B8 -> 0
E21: oFinancials | F21: Link | G21: Financials output sheet | H21: =oFinancials!A8 -> 0 | I21: =oFinancials!B8 -> 0
E22: oDashboard | F22: Link | G22: Dashboard including graphic representation of costs | H22: =oDashboard!A8 -> 0 | I22: =oDashboard!B8 -> 0
E23: SysConfig | F23: Link | G23: Model setup sheet including lists, named ranges and constants | H23: =SysConfig!A8 -> 0 | I23: =SysConfig!B8 -> 0
E24: SysTime | F24: Link | G24: The model timeline and timing flags are generated on this sheet | H24: =SysTime!A8 -> 0 | I24: =SysTime!B8 -> 0
E25: INSERT NEW ROWS ABOVE THIS ROW
E27: Master Control Check | H27: =IFERROR(SUM(H12:H25),1) -> 0 | I27: =IFERROR(SUM(I12:I25),1) -> 0
D29: Model Map
E31: The map below indicates the flow between worksheets within the Model
D54: END OF WORKSHEET - INSERT ROWS ABOVE

Sheet Inputs>>

Sheet iControl
C1: THIS CASE STUDY MODEL IS FOR ILLUSTRATIVE PURPOSES
C2: =cstProjectName -> Should Cost Modelling Case Study - Illustrative SCM
C3: =MID(CELL("filename",A1),FIND("]",CELL("filename",A1))+1,256)&" Sheet" -> iControl Sheet
C4: =IF(ISBLANK(cstProtectiveMarking),"",cstProtectiveMarking) -> Not Protectively Marked
C5: =HYPERLINK("#'Contents'!A1",sysChkWord) -> All Checks OK
C6: =HYPERLINK("#'Contents'!A1","Click for Contents") -> Click for Contents
A8: =SUM(A9:A26) -> 0 | B8: =SUM(B9:B26) -> 0
D10: 1 | E10: Planned Maximum Call Volumes Scenarios
F12: Active Scenario | M12: <<<Select from Drop Down List
A14: =IF(ActiveCallVolumeScenarioIndex=0,1,0) -> 0 | F14: ActiveCallVolumeScenarioIndex | G14: # | I14: 1
F16: Annual Call Volume Reduction | G16: =cstPercent -> % | I16: 0.1
F18: Annual Call Volumes | G18: =cstHours -> Hrs | I18: =cVolumetrics!$K$39 -> 90000
D20: 2 | E20: Cost Scenarios
F22: Active Scenario | M22: <<<Select from Drop Down List
A24: =IF(ActiveCostScenarioIndex=0,1,0) -> 0 | F24: ActiveCostScenarioIndex | G24: # | I24: 2
D26: END OF WORKSHEET - INSERT ROWS ABOVE

Sheet iOptions
C1: THIS CASE STUDY MODEL IS FOR ILLUSTRATIVE PURPOSES
C2: =cstProjectName -> Should Cost Modelling Case Study - Illustrative SCM
C3: =MID(CELL("filename",A1),FIND("]",CELL("filename",A1))+1,256)&" Sheet" -> iOptions Sheet
C4: =IF(ISBLANK(cstProtectiveMarking),"",cstProtectiveMarking) -> Not Protectively Marked
C5: =HYPERLINK("#'Contents'!A1",sysChkWord) -> All Checks OK
C6: =HYPERLINK("#'Contents'!A1","Click for Contents") -> Click for Contents
N7: Time Independent
A8: =SUM(A9:A181) -> 0 | B8: =SUM(B9:B181) -> 0 | G8: Units | I8: BoA / DL Ref | K8: Comments | M8: =SysConfig!F101 -> Low Case | N8: =SysConfig!F102 -> Base Case | O8: =SysConfig!F103 -> High Case | Q8: Inflation Rate
D10: 1 | E10: Call Volumes (All Options)
E12: 1.1 | F12: Planned Call Volumes
F14: Planned Maximum Annual Call Volume Capacity
F16: =SysConfig!F95 -> Scenario A | G16: =cstHours -> Hrs | I16: 1 | N16: 100000
F17: =SysConfig!F96 -> Scenario B | G17: =cstHours -> Hrs | I17: 1 | N17: 150000
F18: =SysConfig!F97 -> Scenario C | G18: =cstHours -> Hrs | I18: 1 | N18: 200000
D20: 2 | E20: Staffing Inputs
E22: 2.1 | F22: Agents
F24: Annualised Hours & Productivity
A26: =IF(N26=0,1,0) -> 0 | F26: Agent Annualised Hours | G26: =cstHours -> Hrs | I26: 2 | N26: 1912
A28: =IF(OR(M28<=0,M28>1,N28<=0,N28>1,O28<=0,O28>1),1,0) -> 0 | F28: Agent Productivity Rate | G28: =cstPercent -> % | I28: 3 | M28: 0.75 | N28: 0.8 | O28: 0.85
E30: 2.2 | F30: Supervisors
F32: Agent to Supervisor Ratio
A34: =IF(OR(M34=0,N34=0,O34=0),1,0) -> 0 | F34: Agent to Supervisor Ratio | G34: =cstNum -> # | I34: 4 | M34: 13 | N34: 15 | O34: 17
E36: 2.3 Admin & Support
F38: Staff Numbers
F40: Reception & Admin Support | G40: =cstNum -> # | I40: 5 | N40: 3
F41: IT Support | G41: =cstNum -> # | I41: 5 | N41: 2
F42: Office Manager | G42: =cstNum -> # | I42: 5 | N42: 1
F43: Office Deputy | G43: =cstNum -> # | I43: 5 | N43: 1
E45: 2.4 Staff Costs by Role
F47: Fully Loaded Annual Staff Costs by Role
A49: =IF(ISNA(MATCH(Q49,iIndices!$F$16:$F$21,0)),1,0) -> 0 | F49: Agents | G49: =cstConstantUnit -> £ 2022/23 | I49: 6 | M49: 26000 | N49: 29000 | O49: 33000 | Q49: Wage Inflation
A50: =IF(ISNA(MATCH(Q50,iIndices!$F$16:$F$21,0)),1,0) -> 0 | F50: Supervisors | G50: =cstConstantUnit -> £ 2022/23 | I50: 6 | M50: 34000 | N50: 38000 | O50: 44000 | Q50: Wage Inflation
A51: =IF(ISNA(MATCH(Q51,iIndices!$F$16:$F$21,0)),1,0) -> 0 | F51: Reception & Admin Support | G51: =cstConstantUnit -> £ 2022/23 | I51: 6 | M51: 24000 | N51: 27000 | O51: 31000 | Q51: Wage Inflation
A52: =IF(ISNA(MATCH(Q52,iIndices!$F$16:$F$21,0)),1,0) -> 0 | F52: IT Support | G52: =cstConstantUnit -> £ 2022/23 | I52: 6 | M52: 32000 | N52: 36000 | O52: 41000 | Q52: Wage Inflation
A53: =IF(ISNA(MATCH(Q53,iIndices!$F$16:$F$21,0)),1,0) -> 0 | F53: Office Manager | G53: =cstConstantUnit -> £ 2022/23 | I53: 6 | M53: 46000 | N53: 51000 | O53: 59000 | Q53: Wage Inflation
A54: =IF(ISNA(MATCH(Q54,iIndices!$F$16:$F$21,0)),1,0) -> 0 | F54: Office Deputy | G54: =cstConstantUnit -> £ 2022/23 | I54: 6 | M54: 36000 | N54: 40000 | O54: 46000 | Q54: Wage Inflation
D56: 3 | E56: Software & Hardware Costs (Lease & Operate and Build & Operate Options)
E58: 3.1 | F58: Telephony Costs
F60: Software
A62: =IF(ISNA(MATCH(Q62,iIndices!$F$16:$F$21,0)),1,0) -> 0 | F62: Application Cost | G62: =cstConstantUnit -> £ 2022/23 | I62: 7 | M62: 175000 | N62: 200000 | O62: 225000 | Q62: Other Inflation
...

Sheet iIndices
C1: THIS CASE STUDY MODEL IS FOR ILLUSTRATIVE PURPOSES
C2: =cstProjectName -> Should Cost Modelling Case Study - Illustrative SCM | Z2: =SysTime!Z2 -> Period Start | AA2: =SysTime!AA2 -> 44652 | AB2: =SysTime!AB2 -> 45017 | AC2: =SysTime!AC2 -> 45383 | AD2: =SysTime!AD2 -> 45748 | AE2: =SysTime!AE2 -> 46113 | AF2: =SysTime!AF2 -> 46478 | AG2: =SysTime!AG2 -> 46844 | ... BE2: =SysTime!BE2 -> 55610 | BG2: =SysTime!BG2 -> 44652 | BH2: =SysTime!BH2 -> 45017 | BI2: =SysTime!BI2 -> 46844 | BJ2: =SysTime!BJ2 -> 48670 | BK2: =SysTime!BK2 -> 50496 | BL2: =SysTime!BL2 -> 52322 | BM2: =SysTime!BM2 -> 54149
C3: =MID(CELL("filename",A1),FIND("]",CELL("filename",A1))+1,256)&" Sheet" -> iIndices Sheet | Z3: =SysTime!Z3 -> Period End | AA3: =SysTime!AA3 -> 45016 | AB3: =SysTime!AB3 -> 45382 | AC3: =SysTime!AC3 -> 45747 | AD3: =SysTime!AD3 -> 46112 | AE3: =SysTime!AE3 -> 46477 | AF3: =SysTime!AF3 -> 46843 | AG3: =SysTime!AG3 -> 47208 | ... BE3: =SysTime!BE3 -> 55974 | BG3: =SysTime!BG3 -> 45016 | BH3: =SysTime!BH3 -> 46843 | BI3: =SysTime!BI3 -> 48669 | BJ3: =SysTime!BJ3 -> 50495 | BK3: =SysTime!BK3 -> 52321 | BL3: =SysTime!BL3 -> 54148 | BM3: =SysTime!BM3 -> 55974
C4: =IF(ISBLANK(cstProtectiveMarking),"",cstProtectiveMarking) -> Not Protectively Marked | Z4: =SysTime!Z4 -> Timeline | AA4: =SysTime!AA4 -> Annual | AB4: =SysTime!AB4 -> Annual | AC4: =SysTime!AC4 -> Annual | AD4: =SysTime!AD4 -> Annual | AE4: =SysTime!AE4 -> Annual | AF4: =SysTime!AF4 -> Annual | AG4: =SysTime!AG4 -> Annual | ... BE4: =SysTime!BE4 -> Annual | BG4: =SysTime!BG4 -> Annual | BH4: =SysTime!BH4 -> 5 Yearly | BI4: =SysTime!BI4 -> 5 Yearly | BJ4: =SysTime!BJ4 -> 5 Yearly | BK4: =SysTime!BK4 -> 5 Yearly | BL4: =SysTime!BL4 -> 5 Yearly | BM4: =SysTime!BM4 -> 5 Yearly
C5: =HYPERLINK("#'Contents'!A1",sysChkWord) -> All Checks OK | Z5: =SysTime!Z5 -> Period index | AA5: =SysTime!AA5 -> 1 | AB5: =SysTime!AB5 -> 2 | AC5: =SysTime!AC5 -> 3 | AD5: =SysTime!AD5 -> 4 | AE5: =SysTime!AE5 -> 5 | AF5: =SysTime!AF5 -> 6 | AG5: =SysTime!AG5 -> 7 | ... BE5: =SysTime!BE5 -> 31 | BG5: =SysTime!BG5 -> 1 | BH5: =SysTime!BH5 -> 2 | BI5: =SysTime!BI5 -> 3 | BJ5: =SysTime!BJ5 -> 4 | BK5: =SysTime!BK5 -> 5 | BL5: =SysTime!BL5 -> 6 | BM5: =SysTime!BM5 -> 7
C6: =HYPERLINK("#'Contents'!A1","Click for Contents") -> Click for Contents | Z6: =SysTime!Z6 -> Year index | AA6: =SysTime!AA6 -> 1 | AB6: =SysTime!AB6 -> 2 | AC6: =SysTime!AC6 -> 3 | AD6: =SysTime!AD6 -> 4 | AE6: =SysTime!AE6 -> 5 | AF6: =SysTime!AF6 -> 6 | AG6: =SysTime!AG6 -> 7 | ... BE6: =SysTime!BE6 -> 31 | BG6: =SysTime!BG6 -> 0 | BH6: =SysTime!BH6 -> 0 | BI6: =SysTime!BI6 -> 0 | BJ6: =SysTime!BJ6 -> 0 | BK6: =SysTime!BK6 -> 0 | BL6: =SysTime!BL6 -> 0 | BM6: =SysTime!BM6 -> 0
Z7: =SysTime!Z7 -> Relative period | AA7: =SysTime!AA7 -> 1 | AB7: =SysTime!AB7 -> 2 | AC7: =SysTime!AC7 -> 3 | AD7: =SysTime!AD7 -> 4 | AE7: =SysTime!AE7 -> 5 | AF7: =SysTime!AF7 -> 6 | AG7: =SysTime!AG7 -> 7 | ... BE7: =SysTime!BE7 -> 31 | BG7: =SysTime!BG7 -> 1 | BH7: =SysTime!BH7 -> 2 | BI7: =SysTime!BI7 -> 3 | BJ7: =SysTime!BJ7 -> 4 | BK7: =SysTime!BK7 -> 5 | BL7: =SysTime!BL7 -> 6 | BM7: =SysTime!BM7 -> 7
A8: =SUM(A9:A29) -> 0 | B8: =SUM(B9:B29) -> 0 | G8: Units | I8: BoA / DL Ref | K8: Comments
D10: 1 | E10: Indexes
E12: 1.1 | F12: Inflation Assumptions
F14: Annual Inflation Rates
F15: Named range
F16: Wage Inflation | G16: % | I16: 36 | AB16: 0.025 | AC16: 0.025 | AD16: 0.025 | AE16: 0.025 | AF16: 0.025 | AG16: 0.025 | AH16: 0.025 | AI16: 0.025 | AJ16: 0.025 | AK16: 0.025 | AL16: 0.025 | AM16: 0.025 | AN16: 0.025 | AO16: 0.025 | AP16: 0.025 | AQ16: 0.025 | AR16: 0.025 | AS16: 0.025 | AT16: 0.025 | AU16: 0.025 | AV16: 0.025 | AW16: 0.025 | AX16: 0.025 | AY16: 0.025 | AZ16: 0.025 | BA16: 0.025 | BB16: 0.025 | BC16: 0.025 | BD16: 0.025 | BE16: 0.025
F17: Other Inflation | G17: % | I17: 36 | AB17: 0.03 | AC17: 0.03 | AD17: 0.03 | AE17: 0.03 | AF17: 0.03 | AG17: 0.03 | AH17: 0.03 | AI17: 0.03 | AJ17: 0.03 | AK17: 0.03 | AL17: 0.03 | AM17: 0.03 | AN17: 0.03 | AO17: 0.03 | AP17: 0.03 | AQ17: 0.03 | AR17: 0.03 | AS17: 0.03 | AT17: 0.03 | AU17: 0.03 | AV17: 0.03 | AW17: 0.03 | AX17: 0.03 | AY17: 0.03 | AZ17: 0.03 | BA17: 0.03 | BB17: 0.03 | BC17: 0.03 | BD17: 0.03 | BE17: 0.03
F18: Inflation Type C | G18: % | I18: 36 | AB18: 0.02 | AC18: 0.02 | AD18: 0.02 | AE18: 0.02 | AF18: 0.02 | AG18: 0.02 | AH18: 0.02 | AI18: 0.02 | AJ18: 0.02 | AK18: 0.02 | AL18: 0.02 | AM18: 0.02 | AN18: 0.02 | AO18: 0.02 | AP18: 0.02 | AQ18: 0.02 | AR18: 0.02 | AS18: 0.02 | AT18: 0.02 | AU18: 0.02 | AV18: 0.02 | AW18: 0.02 | AX18: 0.02 | AY18: 0.02 | AZ18: 0.02 | BA18: 0.02 | BB18: 0.02 | BC18: 0.02 | BD18: 0.02 | BE18: 0.02
F19: Inflation Type D | G19: % | I19: 36 | AB19: 0.02 | AC19: 0.02 | AD19: 0.02 | AE19: 0.02 | AF19: 0.02 | AG19: 0.02 | AH19: 0.02 | AI19: 0.02 | AJ19: 0.02 | AK19: 0.02 | AL19: 0.02 | AM19: 0.02 | AN19: 0.02 | AO19: 0.02 | AP19: 0.02 | AQ19: 0.02 | AR19: 0.02 | AS19: 0.02 | AT19: 0.02 | AU19: 0.02 | AV19: 0.02 | AW19: 0.02 | AX19: 0.02 | AY19: 0.02 | AZ19: 0.02 | BA19: 0.02 | BB19: 0.02 | BC19: 0.02 | BD19: 0.02 | BE19: 0.02
F20: Inflation Type E | G20: % | I20: 36 | AB20: 0.02 | AC20: 0.02 | AD20: 0.02 | AE20: 0.02 | AF20: 0.02 | AG20: 0.02 | AH20: 0.02 | AI20: 0.02 | AJ20: 0.02 | AK20: 0.02 | AL20: 0.02 | AM20: 0.02 | AN20: 0.02 | AO20: 0.02 | AP20: 0.02 | AQ20: 0.02 | AR20: 0.02 | AS20: 0.02 | AT20: 0.02 | AU20: 0.02 | AV20: 0.02 | AW20: 0.02 | AX20: 0.02 | AY20: 0.02 | AZ20: 0.02 | BA20: 0.02 | BB20: 0.02 | BC20: 0.02 | BD20: 0.02 | BE20: 0.02
E22: 1.2 | F22: Discount Factors
F24: Treasury Rates
F26: GDP Deflator (General Price Inflation) | G26: % | I26: 37 | AB26: 0.013 | AC26: 0.017 | AD26: 0.019 | AE26: 0.019 | AF26: 0.02 | AG26: 0.02 | AH26: 0.02 | AI26: 0.02 | AJ26: 0.02 | AK26: 0.02 | AL26: 0.02 | AM26: 0.02 | AN26: 0.02 | AO26: 0.02 | AP26: 0.02 | AQ26: 0.02 | AR26: 0.02 | AS26: 0.02 | AT26: 0.02 | AU26: 0.02 | AV26: 0.02 | AW26: 0.02 | AX26: 0.02 | AY26: 0.02 | AZ26: 0.02 | BA26: 0.02 | BB26: 0.02 | BC26: 0.02 | BD26: 0.02 | BE26: 0.02
F27: Treasury Real Discount Rate | G27: % | I27: 38 | AB27: 0.035 | AC27: 0.035 | AD27: 0.035 | AE27: 0.035 | AF27: 0.035 | AG27: 0.035 | AH27: 0.035 | AI27: 0.035 | AJ27: 0.035 | AK27: 0.035 | AL27: 0.035 | AM27: 0.035 | AN27: 0.035 | AO27: 0.035 | AP27: 0.035 | AQ27: 0.035 | AR27: 0.035 | AS27: 0.035 | AT27: 0.035 | AU27: 0.035 | AV27: 0.035 | AW27: 0.035 | AX27: 0.035 | AY27: 0.035 | AZ27: 0.035 | BA27: 0.035 | BB27: 0.035 | BC27: 0.035 | BD27: 0.035 | BE27: 0.03
D29: END OF WORKSHEET - INSERT ROWS ABOVE

Sheet Calcs>>

Sheet cFactors
C1: THIS CASE STUDY MODEL IS FOR ILLUSTRATIVE PURPOSES
C2: =cstProjectName -> Should Cost Modelling Case Study - Illustrative SCM | Z2: =SysTime!Z2 -> Period Start | AA2: =SysTime!AA2 -> 44652 | AB2: =SysTime!AB2 -> 45017 | AC2: =SysTime!AC2 -> 45383 | AD2: =SysTime!AD2 -> 45748 | AE2: =SysTime!AE2 -> 46113 | AF2: =SysTime!AF2 -> 46478 | AG2: =SysTime!AG2 -> 46844 | ... BE2: =SysTime!BE2 -> 55610 | BG2: =SysTime!BG2 -> 44652 | BH2: =SysTime!BH2 -> 45017 | BI2: =SysTime!BI2 -> 46844 | BJ2: =SysTime!BJ2 -> 48670 | BK2: =SysTime!BK2 -> 50496 | BL2: =SysTime!BL2 -> 52322 | BM2: =SysTime!BM2 -> 54149
C3: =MID(CELL("filename",A1),FIND("]",CELL("filename",A1))+1,256)&" Sheet" -> cFactors Sheet | Z3: =SysTime!Z3 -> Period End | AA3: =SysTime!AA3 -> 45016 | AB3: =SysTime!AB3 -> 45382 | AC3: =SysTime!AC3 -> 45747 | AD3: =SysTime!AD3 -> 46112 | AE3: =SysTime!AE3 -> 46477 | AF3: =SysTime!AF3 -> 46843 | AG3: =SysTime!AG3 -> 47208 | ... BE3: =SysTime!BE3 -> 55974 | BG3: =SysTime!BG3 -> 45016 | BH3: =SysTime!BH3 -> 46843 | BI3: =SysTime!BI3 -> 48669 | BJ3: =SysTime!BJ3 -> 50495 | BK3: =SysTime!BK3 -> 52321 | BL3: =SysTime!BL3 -> 54148 | BM3: =SysTime!BM3 -> 55974
C4: =IF(ISBLANK(cstProtectiveMarking),"",cstProtectiveMarking) -> Not Protectively Marked | Z4: =SysTime!Z4 -> Timeline | AA4: =SysTime!AA4 -> Annual | AB4: =SysTime!AB4 -> Annual | AC4: =SysTime!AC4 -> Annual | AD4: =SysTime!AD4 -> Annual | AE4: =SysTime!AE4 -> Annual | AF4: =SysTime!AF4 -> Annual | AG4: =SysTime!AG4 -> Annual | ... BE4: =SysTime!BE4 -> Annual | BG4: =SysTime!BG4 -> Annual | BH4: =SysTime!BH4 -> 5 Yearly | BI4: =SysTime!BI4 -> 5 Yearly | BJ4: =SysTime!BJ4 -> 5 Yearly | BK4: =SysTime!BK4 -> 5 Yearly | BL4: =SysTime!BL4 -> 5 Yearly | BM4: =SysTime!BM4 -> 5 Yearly
C5: =HYPERLINK("#'Contents'!A1",sysChkWord) -> All Checks OK | Z5: =SysTime!Z5 -> Period index | AA5: =SysTime!AA5 -> 1 | AB5: =SysTime!AB5 -> 2 | AC5: =SysTime!AC5 -> 3 | AD5: =SysTime!AD5 -> 4 | AE5: =SysTime!AE5 -> 5 | AF5: =SysTime!AF5 -> 6 | AG5: =SysTime!AG5 -> 7 | ... BE5: =SysTime!BE5 -> 31 | BG5: =SysTime!BG5 -> 1 | BH5: =SysTime!BH5 -> 2 | BI5: =SysTime!BI5 -> 3 | BJ5: =SysTime!BJ5 -> 4 | BK5: =SysTime!BK5 -> 5 | BL5: =SysTime!BL5 -> 6 | BM5: =SysTime!BM5 -> 7
C6: =HYPERLINK("#'Contents'!A1","Click for Contents") -> Click for Contents | Z6: =SysTime!Z6 -> Year index | AA6: =SysTime!AA6 -> 1 | AB6: =SysTime!AB6 -> 2 | AC6: =SysTime!AC6 -> 3 | AD6: =SysTime!AD6 -> 4 | AE6: =SysTime!AE6 -> 5 | AF6: =SysTime!AF6 -> 6 | AG6: =SysTime!AG6 -> 7 | ... BE6: =SysTime!BE6 -> 31 | BG6: =SysTime!BG6 -> 0 | BH6: =SysTime!BH6 -> 0 | BI6: =SysTime!BI6 -> 0 | BJ6: =SysTime!BJ6 -> 0 | BK6: =SysTime!BK6 -> 0 | BL6: =SysTime!BL6 -> 0 | BM6: =SysTime!BM6 -> 0
Z7: =SysTime!Z7 -> Relative period | AA7: =SysTime!AA7 -> 1 | AB7: =SysTime!AB7 -> 2 | AC7: =SysTime!AC7 -> 3 | AD7: =SysTime!AD7 -> 4 | AE7: =SysTime!AE7 -> 5 | AF7: =SysTime!AF7 -> 6 | AG7: =SysTime!AG7 -> 7 | ... BE7: =SysTime!BE7 -> 31 | BG7: =SysTime!BG7 -> 1 | BH7: =SysTime!BH7 -> 2 | BI7: =SysTime!BI7 -> 3 | BJ7: =SysTime!BJ7 -> 4 | BK7: =SysTime!BK7 -> 5 | BL7: =SysTime!BL7 -> 6 | BM7: =SysTime!BM7 -> 7
A8: =SUM(A9:A48) -> 0 | B8: =SUM(B9:B48) -> 0 | G8: Units
D10: 1 | E10: Call-Ups
E12: 1.1 | F12: Inflation Assumptions
F14: Annual Inflation Rates
F16: Wage Inflation | G16: % | AA16: =iIndices!AA16 -> 0 | AB16: =iIndices!AB16 -> 0.025 | AC16: =iIndices!AC16 -> 0.025 | AD16: =iIndices!AD16 -> 0.025 | AE16: =iIndices!AE16 -> 0.025 | AF16: =iIndices!AF16 -> 0.025 | AG16: =iIndices!AG16 -> 0.025 | AH16: =iIndices!AH16 -> 0.025 | ... BE16: =iIndices!BE16 -> 0.025
F17: Other Inflation | G17: % | AA17: =iIndices!AA17 -> 0 | AB17: =iIndices!AB17 -> 0.03 | AC17: =iIndices!AC17 -> 0.03 | AD17: =iIndices!AD17 -> 0.03 | AE17: =iIndices!AE17 -> 0.03 | AF17: =iIndices!AF17 -> 0.03 | AG17: =iIndices!AG17 -> 0.03 | AH17: =iIndices!AH17 -> 0.03 | ... BE17: =iIndices!BE17 -> 0.03
F18: Inflation Type C | G18: % | AA18: =iIndices!AA18 -> 0 | AB18: =iIndices!AB18 -> 0.02 | AC18: =iIndices!AC18 -> 0.02 | AD18: =iIndices!AD18 -> 0.02 | AE18: =iIndices!AE18 -> 0.02 | AF18: =iIndices!AF18 -> 0.02 | AG18: =iIndices!AG18 -> 0.02 | AH18: =iIndices!AH18 -> 0.02 | ... BE18: =iIndices!BE18 -> 0.02
F19: Inflation Type D | G19: % | AA19: =iIndices!AA19 -> 0 | AB19: =iIndices!AB19 -> 0.02 | AC19: =iIndices!AC19 -> 0.02 | AD19: =iIndices!AD19 -> 0.02 | AE19: =iIndices!AE19 -> 0.02 | AF19: =iIndices!AF19 -> 0.02 | AG19: =iIndices!AG19 -> 0.02 | AH19: =iIndices!AH19 -> 0.02 | ... BE19: =iIndices!BE19 -> 0.02
F20: Inflation Type E | G20: % | AA20: =iIndices!AA20 -> 0 | AB20: =iIndices!AB20 -> 0.02 | AC20: =iIndices!AC20 -> 0.02 | AD20: =iIndices!AD20 -> 0.02 | AE20: =iIndices!AE20 -> 0.02 | AF20: =iIndices!AF20 -> 0.02 | AG20: =iIndices!AG20 -> 0.02 | AH20: =iIndices!AH20 -> 0.02 | ... BE20: =iIndices!BE20 -> 0.02
E22: 1.2 | F22: Discount Rate
F24: Treasury Rates
F26: GDP Deflator (General Price Inflation) | G26: % | AA26: =iIndices!AA26 -> 0 | AB26: =iIndices!AB26 -> 0.013 | AC26: =iIndices!AC26 -> 0.017 | AD26: =iIndices!AD26 -> 0.019 | AE26: =iIndices!AE26 -> 0.019 | AF26: =iIndices!AF26 -> 0.02 | AG26: =iIndices!AG26 -> 0.02 | AH26: =iIndices!AH26 -> 0.02 | ... BE26: =iIndices!BE26 -> 0.02
F27: Treasury Real Discount Rate | G27: % | AA27: =iIndices!AA27 -> 0 | AB27: =iIndices!AB27 -> 0.035 | AC27: =iIndices!AC27 -> 0.035 | AD27: =iIndices!AD27 -> 0.035 | AE27: =iIndices!AE27 -> 0.035 | AF27: =iIndices!AF27 -> 0.035 | AG27: =iIndices!AG27 -> 0.035 | AH27: =iIndices!AH27 -> 0.035 | ... BE27: =iIndices!BE27 -> 0.03
D29: 2 | E29: Calculations
E31: 2.1 | F31: Inflation Index
F33: Annual Inflation Index
A35: =IF(MIN(AA35:BE35)<0,1,0) -> 0 | F35: Wage Inflation | G35: % | AA35: =IF(AA$5=1,1,Z35)*(1+AA16) -> 1 | AB35: =IF(AB$5=1,1,AA35)*(1+AB16) -> 1.025 | AC35: =IF(AC$5=1,1,AB35)*(1+AC16) -> 1.050625 | AD35: =IF(AD$5=1,1,AC35)*(1+AD16) -> 1.0768906 | AE35: =IF(AE$5=1,1,AD35)*(1+AE16) -> 1.1038129 | AF35: =IF(AF$5=1,1,AE35)*(1+AF16) -> 1.1314082 | AG35: =IF(AG$5=1,1,AF35)*(1+AG16) -> 1.1596934 | AH35: =IF(AH$5=1,1,AG35)*(1+AH16) -> 1.1886858 | ... BE35: =IF(BE$5=1,1,BD35)*(1+BE16) -> 2.0975676
A36: =IF(MIN(AA36:BE36)<0,1,0) -> 0 | F36: Other Inflation | G36: % | AA36: =IF(AA$5=1,1,Z36)*(1+AA17) -> 1 | AB36: =IF(AB$5=1,1,AA36)*(1+AB17) -> 1.03 | AC36: =IF(AC$5=1,1,AB36)*(1+AC17) -> 1.0609 | AD36: =IF(AD$5=1,1,AC36)*(1+AD17) -> 1.092727 | AE36: =IF(AE$5=1,1,AD36)*(1+AE17) -> 1.1255088 | AF36: =IF(AF$5=1,1,AE36)*(1+AF17) -> 1.1592741 | AG36: =IF(AG$5=1,1,AF36)*(1+AG17) -> 1.1940523 | AH36: =IF(AH$5=1,1,AG36)*(1+AH17) -> 1.2298739 | ... BE36: =IF(BE$5=1,1,BD36)*(1+BE17) -> 2.4272625
A37: =IF(MIN(AA37:BE37)<0,1,0) -> 0 | F37: Inflation Type C | G37: % | AA37: =IF(AA$5=1,1,Z37)*(1+AA18) -> 1 | AB37: =IF(AB$5=1,1,AA37)*(1+AB18) -> 1.02 | AC37: =IF(AC$5=1,1,AB37)*(1+AC18) -> 1.0404 | AD37: =IF(AD$5=1,1,AC37)*(1+AD18) -> 1.061208 | AE37: =IF(AE$5=1,1,AD37)*(1+AE18) -> 1.0824322 | AF37: =IF(AF$5=1,1,AE37)*(1+AF18) -> 1.1040808 | AG37: =IF(AG$5=1,1,AF37)*(1+AG18) -> 1.1261624 | AH37: =IF(AH$5=1,1,AG37)*(1+AH18) -> 1.1486857 | ... BE37: =IF(BE$5=1,1,BD37)*(1+BE18) -> 1.8113616
A38: =IF(MIN(AA38:BE38)<0,1,0) -> 0 | F38: Inflation Type D | G38: % | AA38: =IF(AA$5=1,1,Z38)*(1+AA19) -> 1 | AB38: =IF(AB$5=1,1,AA38)*(1+AB19) -> 1.02 | AC38: =IF(AC$5=1,1,AB38)*(1+AC19) -> 1.0404 | AD38: =IF(AD$5=1,1,AC38)*(1+AD19) -> 1.061208 | AE38: =IF(AE$5=1,1,AD38)*(1+AE19) -> 1.0824322 | AF38: =IF(AF$5=1,1,AE38)*(1+AF19) -> 1.1040808 | AG38: =IF(AG$5=1,1,AF38)*(1+AG19) -> 1.1261624 | AH38: =IF(AH$5=1,1,AG38)*(1+AH19) -> 1.1486857 | ... BE38: =IF(BE$5=1,1,BD38)*(1+BE19) -> 1.8113616
A39: =IF(MIN(AA39:BE39)<0,1,0) -> 0 | F39: Inflation Type E | G39: % | AA39: =IF(AA$5=1,1,Z39)*(1+AA20) -> 1 | AB39: =IF(AB$5=1,1,AA39)*(1+AB20) -> 1.02 | AC39: =IF(AC$5=1,1,AB39)*(1+AC20) -> 1.0404 | AD39: =IF(AD$5=1,1,AC39)*(1+AD20) -> 1.061208 | AE39: =IF(AE$5=1,1,AD39)*(1+AE20) -> 1.0824322 | AF39: =IF(AF$5=1,1,AE39)*(1+AF20) -> 1.1040808 | AG39: =IF(AG$5=1,1,AF39)*(1+AG20) -> 1.1261624 | AH39: =IF(AH$5=1,1,AG39)*(1+AH20) -> 1.1486857 | ... BE39: =IF(BE$5=1,1,BD39)*(1+BE20) -> 1.8113616
E41: 2.2 | F41: Discount Factors
F43: Treasury Rates
A45: =IF(MIN(AA45:BE45)<0,1,0) -> 0 | F45: GDP Deflator (General Price Inflation) | G45: % | AA45: =IF(AA$5=1,1,Z45)/(1+AA26) -> 1 | AB45: =IF(AB$5=1,1,AA45)/(1+AB26) -> 0.98716683 | AC45: =IF(AC$5=1,1,AB45)/(1+AC26) -> 0.97066552 | AD45: =IF(AD$5=1,1,AC45)/(1+AD26) -> 0.95256675 | AE45: =IF(AE$5=1,1,AD45)/(1+AE26) -> 0.93480545 | AF45: =IF(AF$5=1,1,AE45)/(1+AF26) -> 0.91647593 | AG45: =IF(AG$5=1,1,AF45)/(1+AG26) -> 0.89850581 | AH45: =IF(AH$5=1,1,AG45)/(1+AH26) -> 0.88088805 | ... BE45: =IF(BE$5=1,1,BD45)/(1+BE26) -> 0.55862037
A46: =IF(MIN(AA46:BE46)<0,1,0) -> 0 | F46: Treasury Real Discount Rate | G46: % | AA46: =IF(AA$5=1,1,Z46)/(1+AA27) -> 1 | AB46: =IF(AB$5=1,1,AA46)/(1+AB27) -> 0.96618357 | AC46: =IF(AC$5=1,1,AB46)/(1+AC27) -> 0.9335107 | AD46: =IF(AD$5=1,1,AC46)/(1+AD27) -> 0.90194271 | AE46: =IF(AE$5=1,1,AD46)/(1+AE27) -> 0.87144223 | AF46: =IF(AF$5=1,1,AE46)/(1+AF27) -> 0.84197317 | AG46: =IF(AG$5=1,1,AF46)/(1+AG27) -> 0.81350064 | AH46: =IF(AH$5=1,1,AG46)/(1+AH27) -> 0.78599096 | ... BE46: =IF(BE$5=1,1,BD46)/(1+BE27) -> 0.35800792
D48: END OF WORKSHEET - INSERT ROWS ABOVE

Sheet cVolumetrics
C1: THIS CASE STUDY MODEL IS FOR ILLUSTRATIVE PURPOSES
C2: =cstProjectName -> Should Cost Modelling Case Study - Illustrative SCM | Z2: =SysTime!Z2 -> Period Start | AA2: =SysTime!AA2 -> 44652 | AB2: =SysTime!AB2 -> 45017 | AC2: =SysTime!AC2 -> 45383 | AD2: =SysTime!AD2 -> 45748 | AE2: =SysTime!AE2 -> 46113 | AF2: =SysTime!AF2 -> 46478 | AG2: =SysTime!AG2 -> 46844 | ... BE2: =SysTime!BE2 -> 55610 | BG2: =SysTime!BG2 -> 44652 | BH2: =SysTime!BH2 -> 45017 | BI2: =SysTime!BI2 -> 46844 | BJ2: =SysTime!BJ2 -> 48670 | BK2: =SysTime!BK2 -> 50496 | BL2: =SysTime!BL2 -> 52322 | BM2: =SysTime!BM2 -> 54149
C3: =MID(CELL("filename",A1),FIND("]",CELL("filename",A1))+1,256)&" Sheet" -> cVolumetrics Sheet | Z3: =SysTime!Z3 -> Period End | AA3: =SysTime!AA3 -> 45016 | AB3: =SysTime!AB3 -> 45382 | AC3: =SysTime!AC3 -> 45747 | AD3: =SysTime!AD3 -> 46112 | AE3: =SysTime!AE3 -> 46477 | AF3: =SysTime!AF3 -> 46843 | AG3: =SysTime!AG3 -> 47208 | ... BE3: =SysTime!BE3 -> 55974 | BG3: =SysTime!BG3 -> 45016 | BH3: =SysTime!BH3 -> 46843 | BI3: =SysTime!BI3 -> 48669 | BJ3: =SysTime!BJ3 -> 50495 | BK3: =SysTime!BK3 -> 52321 | BL3: =SysTime!BL3 -> 54148 | BM3: =SysTime!BM3 -> 55974
C4: =IF(ISBLANK(cstProtectiveMarking),"",cstProtectiveMarking) -> Not Protectively Marked | Z4: =SysTime!Z4 -> Timeline | AA4: =SysTime!AA4 -> Annual | AB4: =SysTime!AB4 -> Annual | AC4: =SysTime!AC4 -> Annual | AD4: =SysTime!AD4 -> Annual | AE4: =SysTime!AE4 -> Annual | AF4: =SysTime!AF4 -> Annual | AG4: =SysTime!AG4 -> Annual | ... BE4: =SysTime!BE4 -> Annual | BG4: =SysTime!BG4 -> Annual | BH4: =SysTime!BH4 -> 5 Yearly | BI4: =SysTime!BI4 -> 5 Yearly | BJ4: =SysTime!BJ4 -> 5 Yearly | BK4: =SysTime!BK4 -> 5 Yearly | BL4: =SysTime!BL4 -> 5 Yearly | BM4: =SysTime!BM4 -> 5 Yearly
C5: =HYPERLINK("#'Contents'!A1",sysChkWord) -> All Checks OK | Z5: =SysTime!Z5 -> Period index | AA5: =SysTime!AA5 -> 1 | AB5: =SysTime!AB5 -> 2 | AC5: =SysTime!AC5 -> 3 | AD5: =SysTime!AD5 -> 4 | AE5: =SysTime!AE5 -> 5 | AF5: =SysTime!AF5 -> 6 | AG5: =SysTime!AG5 -> 7 | ... BE5: =SysTime!BE5 -> 31 | BG5: =SysTime!BG5 -> 1 | BH5: =SysTime!BH5 -> 2 | BI5: =SysTime!BI5 -> 3 | BJ5: =SysTime!BJ5 -> 4 | BK5: =SysTime!BK5 -> 5 | BL5: =SysTime!BL5 -> 6 | BM5: =SysTime!BM5 -> 7
C6: =HYPERLINK("#'Contents'!A1","Click for Contents") -> Click for Contents | Z6: =SysTime!Z6 -> Year index | AA6: =SysTime!AA6 -> 1 | AB6: =SysTime!AB6 -> 2 | AC6: =SysTime!AC6 -> 3 | AD6: =SysTime!AD6 -> 4 | AE6: =SysTime!AE6 -> 5 | AF6: =SysTime!AF6 -> 6 | AG6: =SysTime!AG6 -> 7 | ... BE6: =SysTime!BE6 -> 31 | BG6: =SysTime!BG6 -> 0 | BH6: =SysTime!BH6 -> 0 | BI6: =SysTime!BI6 -> 0 | BJ6: =SysTime!BJ6 -> 0 | BK6: =SysTime!BK6 -> 0 | BL6: =SysTime!BL6 -> 0 | BM6: =SysTime!BM6 -> 0
Z7: =SysTime!Z7 -> Relative period | AA7: =SysTime!AA7 -> 1 | AB7: =SysTime!AB7 -> 2 | AC7: =SysTime!AC7 -> 3 | AD7: =SysTime!AD7 -> 4 | AE7: =SysTime!AE7 -> 5 | AF7: =SysTime!AF7 -> 6 | AG7: =SysTime!AG7 -> 7 | ... BE7: =SysTime!BE7 -> 31 | BG7: =SysTime!BG7 -> 1 | BH7: =SysTime!BH7 -> 2 | BI7: =SysTime!BI7 -> 3 | BJ7: =SysTime!BJ7 -> 4 | BK7: =SysTime!BK7 -> 5 | BL7: =SysTime!BL7 -> 6 | BM7: =SysTime!BM7 -> 7
A8: =SUM(A9:A101) -> 0 | B8: =SUM(B9:B101) -> 0 | G8: Units
D10: 1 | E10: Active Scenarios
E12: 1.1 | F12: Scenarios
F14: Planned Maximum Call Volumes Scenario
F16: Cost Scenario
D18: 2 | E18: Date Flags
F20: Operation Flag | G20: Flag | AA20: =SysTime!AA22 -> 0 | AB20: =SysTime!AB22 -> 1 | AC20: =SysTime!AC22 -> 1 | AD20: =SysTime!AD22 -> 1 | AE20: =SysTime!AE22 -> 1 | AF20: =SysTime!AF22 -> 1 | AG20: =SysTime!AG22 -> 1 | AH20: =SysTime!AH22 -> 1 | ... BE20: =SysTime!BE22 -> 1
F22: First Year of Operation | G22: Flag | AA22: =SysTime!AA24 -> 0 | AB22: =SysTime!AB24 -> 1 | AC22: =SysTime!AC24 -> 0 | AD22: =SysTime!AD24 -> 0 | AE22: =SysTime!AE24 -> 0 | AF22: =SysTime!AF24 -> 0 | AG22: =SysTime!AG24 -> 0 | AH22: =SysTime!AH24 -> 0 | ... BE22: =SysTime!BE24 -> 0
F24: First Period of Operation | G24: # | K24: =SysTime!K26 -> 2
F26: Build Year Flag | G26: =cstFlag -> Flag | AA26: =SysTime!AA28 -> 1 | AB26: =SysTime!AB28 -> 0 | AC26: =SysTime!AC28 -> 0 | AD26: =SysTime!AD28 -> 0 | AE26: =SysTime!AE28 -> 0 | AF26: =SysTime!AF28 -> 0 | AG26: =SysTime!AG28 -> 0 | AH26: =SysTime!AH28 -> 0 | ... BE26: =SysTime!BE28 -> 0
D28: 3 | E28: Call Volumes
E30: 3.1 | F30: Annual Call Volumes
F32: Call-Ups
F34: Planned Maximum Annual Call Volume Capacity | G34: =cstHours -> Hrs | K34: {=INDEX(iOptions!$N$16:$N$18,ActiveCallVolumeScenarioIndex)} -> 100000
F35: Annual Call Volume Reduction | G35: =cstPercent -> % | K35: =iControl!$I$16 -> 0.1
F37: Calculations
Z38: Total
A39: =IF(ABS(SUM(AA39:BE39)-SUM(BG39:BM39))<eTol,0,1) -> 0 | F39: Annual Call Volume | G39: =cstHours -> Hrs | K39: =$K34*(1-$K35) -> 90000 | Z39: =SUM(AA39:BE39) -> 2700000 | AA39: =$K$39*AA20 -> 0 | AB39: =$K$39*AB20 -> 90000 | AC39: =$K$39*AC20 -> 90000 | AD39: =$K$39*AD20 -> 90000 | AE39: =$K$39*AE20 -> 90000 | AF39: =$K$39*AF20 -> 90000 | AG39: =$K$39*AG20 -> 90000 | AH39: =$K$39*AH20 -> 90000 | ... BE39: =$K$39*BE20 -> 90000 | BG39: =SUMIFS($AA39:$BE39,$AA$2:$BE$2,">="&BG$2,$AA$3:$BE$3,"<="&BG$3) -> 0 | BH39: =SUMIFS($AA39:$BE39,$AA$2:$BE$2,">="&BH$2,$AA$3:$BE$3,"<="&BH$3) -> 450000 | BI39: =SUMIFS($AA39:$BE39,$AA$2:$BE$2,">="&BI$2,$AA$3:$BE$3,"<="&BI$3) -> 450000 | BJ39: =SUMIFS($AA39:$BE39,$AA$2:$BE$2,">="&BJ$2,$AA$3:$BE$3,"<="&BJ$3) -> 450000 | BK39: =SUMIFS($AA39:$BE39,$AA$2:$BE$2,">="&BK$2,$AA$3:$BE$3,"<="&BK$3) -> 450000 | BL39: =SUMIFS($AA39:$BE39,$AA$2:$BE$2,">="&BL$2,$AA$3:$BE$3,"<="&BL$3) -> 450000 | BM39: =SUMIFS($AA39:$BE39,$AA$2:$BE$2,">="&BM$2,$AA$3:$BE$3,"<="&BM$3) -> 450000
D41: 4 | E41: Staff Volumes
E43: 4.1 | F43: Agents
F45: Call-Ups
F47: Agent Annualised Hours | G47: =cstHours -> Hrs | K47: =iOptions!$N$26 -> 1912
F48: Agent Productivity Rate | G48: =cstPercent -> % | K48: {=INDEX(iOptions!$M$28:$O$28,1,ActiveCostScenarioIndex)} -> 0.8
F50: Calculations
F52: Annual Hours per Agent | G52: =cstNum -> # | AA52: =$K47 -> 1912 | AB52: =$K47 -> 1912 | AC52: =$K47 -> 1912 | AD52: =$K47 -> 1912 | AE52: =$K47 -> 1912 | AF52: =$K47 -> 1912 | AG52: =$K47 -> 1912 | AH52: =$K47 -> 1912 | ... BE52: =$K47 -> 1912
A54: =IF(MIN(AA54:BE54)<0,1,0) -> 0 | F54: Active Number of Agents | G54: =cstNum -> # | AA54: =AA39/AA52 -> 0 | AB54: =AB39/AB52 -> 47.07113 | AC54: =AC39/AC52 -> 47.07113 | AD54: =AD39/AD52 -> 47.07113 | AE54: =AE39/AE52 -> 47.07113 | AF54: =AF39/AF52 -> 47.07113 | AG54: =AG39/AG52 -> 47.07113 | AH54: =AH39/AH52 -> 47.07113 | ... BE54: =BE39/BE52 -> 47.07113
A56: =IF(MIN(AA56:BE56)<0,1,0) -> 0 | F56: Number of Agents | G56: =cstNum -> # | AA56: =AA54/$K48 -> 0 | AB56: =AB54/$K48 -> 58.838912 | AC56: =AC54/$K48 -> 58.838912 | AD56: =AD54/$K48 -> 58.838912 | AE56: =AE54/$K48 -> 58.838912 | AF56: =AF54/$K48 -> 58.838912 | AG56: =AG54/$K48 -> 58.838912 | AH56: =AH54/$K48 -> 58.838912 | ... BE56: =BE54/$K48 -> 58.838912
E58: 4.2 | F58: Supervisors
F60: Call-Ups
F62: Agent to Supervisor Ratio | G62: =cstNum -> # | K62: {=INDEX(iOptions!$M$34:$O$34,1,ActiveCostScenarioIndex)} -> 15
F64: Calculations
A66: =IF(MIN(AA66:BE66)<0,1,0) -> 0 | F66: Active Number of Supervisors | G66: =cstNum -> # | AA66: =AA54/$K62 -> 0 | AB66: =AB54/$K62 -> 3.1380753 | AC66: =AC54/$K62 -> 3.1380753 | AD66: =AD54/$K62 -> 3.1380753 | AE66: =AE54/$K62 -> 3.1380753 | AF66: =AF54/$K62 -> 3.1380753 | AG66: =AG54/$K62 -> 3.1380753 | AH66: =AH54/$K62 -> 3.1380753 | ... BE66: =BE54/$K62 -> 3.1380753
A68: =IF(MIN(AA68:BE68)<0,1,0) -> 0 | F68: Number of Supervisors | G68: =cstNum -> # | AA68: =AA56/$K62 -> 0 | AB68: =AB56/$K62 -> 3.9225941 | AC68: =AC56/$K62 -> 3.9225941 | AD68: =AD56/$K62 -> 3.9225941 | AE68: =AE56/$K62 -> 3.9225941 | AF68: =AF56/$K62 -> 3.9225941 | AG68: =AG56/$K62 -> 3.9225941 | AH68: =AH56/$K62 -> 3.9225941 | ... BE68: =BE56/$K62 -> 3.9225941
...

Sheet cCosts
C1: THIS CASE STUDY MODEL IS FOR ILLUSTRATIVE PURPOSES
C2: =cstProjectName -> Should Cost Modelling Case Study - Illustrative SCM | Z2: =SysTime!Z2 -> Period Start | AA2: =SysTime!AA2 -> 44652 | AB2: =SysTime!AB2 -> 45017 | AC2: =SysTime!AC2 -> 45383 | AD2: =SysTime!AD2 -> 45748 | AE2: =SysTime!AE2 -> 46113 | AF2: =SysTime!AF2 -> 46478 | AG2: =SysTime!AG2 -> 46844 | ... BE2: =SysTime!BE2 -> 55610 | BG2: =SysTime!BG2 -> 44652 | BH2: =SysTime!BH2 -> 45017 | BI2: =SysTime!BI2 -> 46844 | BJ2: =SysTime!BJ2 -> 48670 | BK2: =SysTime!BK2 -> 50496 | BL2: =SysTime!BL2 -> 52322 | BM2: =SysTime!BM2 -> 54149
C3: =MID(CELL("filename",A1),FIND("]",CELL("filename",A1))+1,256)&" Sheet" -> cCosts Sheet | Z3: =SysTime!Z3 -> Period End | AA3: =SysTime!AA3 -> 45016 | AB3: =SysTime!AB3 -> 45382 | AC3: =SysTime!AC3 -> 45747 | AD3: =SysTime!AD3 -> 46112 | AE3: =SysTime!AE3 -> 46477 | AF3: =SysTime!AF3 -> 46843 | AG3: =SysTime!AG3 -> 47208 | ... BE3: =SysTime!BE3 -> 55974 | BG3: =SysTime!BG3 -> 45016 | BH3: =SysTime!BH3 -> 46843 | BI3: =SysTime!BI3 -> 48669 | BJ3: =SysTime!BJ3 -> 50495 | BK3: =SysTime!BK3 -> 52321 | BL3: =SysTime!BL3 -> 54148 | BM3: =SysTime!BM3 -> 55974
C4: =IF(ISBLANK(cstProtectiveMarking),"",cstProtectiveMarking) -> Not Protectively Marked | Z4: =SysTime!Z4 -> Timeline | AA4: =SysTime!AA4 -> Annual | AB4: =SysTime!AB4 -> Annual | AC4: =SysTime!AC4 -> Annual | AD4: =SysTime!AD4 -> Annual | AE4: =SysTime!AE4 -> Annual | AF4: =SysTime!AF4 -> Annual | AG4: =SysTime!AG4 -> Annual | ... BE4: =SysTime!BE4 -> Annual | BG4: =SysTime!BG4 -> Annual | BH4: =SysTime!BH4 -> 5 Yearly | BI4: =SysTime!BI4 -> 5 Yearly | BJ4: =SysTime!BJ4 -> 5 Yearly | BK4: =SysTime!BK4 -> 5 Yearly | BL4: =SysTime!BL4 -> 5 Yearly | BM4: =SysTime!BM4 -> 5 Yearly
C5: =HYPERLINK("#'Contents'!A1",sysChkWord) -> All Checks OK | Z5: =SysTime!Z5 -> Period index | AA5: =SysTime!AA5 -> 1 | AB5: =SysTime!AB5 -> 2 | AC5: =SysTime!AC5 -> 3 | AD5: =SysTime!AD5 -> 4 | AE5: =SysTime!AE5 -> 5 | AF5: =SysTime!AF5 -> 6 | AG5: =SysTime!AG5 -> 7 | ... BE5: =SysTime!BE5 -> 31 | BG5: =SysTime!BG5 -> 1 | BH5: =SysTime!BH5 -> 2 | BI5: =SysTime!BI5 -> 3 | BJ5: =SysTime!BJ5 -> 4 | BK5: =SysTime!BK5 -> 5 | BL5: =SysTime!BL5 -> 6 | BM5: =SysTime!BM5 -> 7
C6: =HYPERLINK("#'Contents'!A1","Click for Contents") -> Click for Contents | Z6: =SysTime!Z6 -> Year index | AA6: =SysTime!AA6 -> 1 | AB6: =SysTime!AB6 -> 2 | AC6: =SysTime!AC6 -> 3 | AD6: =SysTime!AD6 -> 4 | AE6: =SysTime!AE6 -> 5 | AF6: =SysTime!AF6 -> 6 | AG6: =SysTime!AG6 -> 7 | ... BE6: =SysTime!BE6 -> 31 | BG6: =SysTime!BG6 -> 0 | BH6: =SysTime!BH6 -> 0 | BI6: =SysTime!BI6 -> 0 | BJ6: =SysTime!BJ6 -> 0 | BK6: =SysTime!BK6 -> 0 | BL6: =SysTime!BL6 -> 0 | BM6: =SysTime!BM6 -> 0
Z7: =SysTime!Z7 -> Relative period | AA7: =SysTime!AA7 -> 1 | AB7: =SysTime!AB7 -> 2 | AC7: =SysTime!AC7 -> 3 | AD7: =SysTime!AD7 -> 4 | AE7: =SysTime!AE7 -> 5 | AF7: =SysTime!AF7 -> 6 | AG7: =SysTime!AG7 -> 7 | ... BE7: =SysTime!BE7 -> 31 | BG7: =SysTime!BG7 -> 1 | BH7: =SysTime!BH7 -> 2 | BI7: =SysTime!BI7 -> 3 | BJ7: =SysTime!BJ7 -> 4 | BK7: =SysTime!BK7 -> 5 | BL7: =SysTime!BL7 -> 6 | BM7: =SysTime!BM7 -> 7
A8: =SUM(A9:A484) -> 0 | B8: =SUM(B9:B484) -> 0 | G8: Units
D10: 1 | E10: Active Scenarios
E12: 1.1 | F12: Scenarios
F14: Planned Maximum Call Volumes Scenario
F16: Cost Scenario
D18: 2 | E18: Date Flags
F20: Operation Flag | G20: Flag | AA20: =SysTime!AA22 -> 0 | AB20: =SysTime!AB22 -> 1 | AC20: =SysTime!AC22 -> 1 | AD20: =SysTime!AD22 -> 1 | AE20: =SysTime!AE22 -> 1 | AF20: =SysTime!AF22 -> 1 | AG20: =SysTime!AG22 -> 1 | AH20: =SysTime!AH22 -> 1 | ... BE20: =SysTime!BE22 -> 1
F22: First Year of Operation | G22: Flag | AA22: =SysTime!AA24 -> 0 | AB22: =SysTime!AB24 -> 1 | AC22: =SysTime!AC24 -> 0 | AD22: =SysTime!AD24 -> 0 | AE22: =SysTime!AE24 -> 0 | AF22: =SysTime!AF24 -> 0 | AG22: =SysTime!AG24 -> 0 | AH22: =SysTime!AH24 -> 0 | ... BE22: =SysTime!BE24 -> 0
F24: First Period of Operation | G24: # | K24: =SysTime!K26 -> 2
F26: Build Year Flag | G26: =cstFlag -> Flag | AA26: =SysTime!AA28 -> 1 | AB26: =SysTime!AB28 -> 0 | AC26: =SysTime!AC28 -> 0 | AD26: =SysTime!AD28 -> 0 | AE26: =SysTime!AE28 -> 0 | AF26: =SysTime!AF28 -> 0 | AG26: =SysTime!AG28 -> 0 | AH26: =SysTime!AH28 -> 0 | ... BE26: =SysTime!BE28 -> 0
D28: 3 | E28: Inflation Call-Ups
E30: 3.1 | F30: Inflation Index
F32: Annual Inflation Index
F34: =iIndices!F16 -> Wage Inflation | G34: % | AA34: =cFactors!AA35 -> 1 | AB34: =cFactors!AB35 -> 1.025 | AC34: =cFactors!AC35 -> 1.050625 | AD34: =cFactors!AD35 -> 1.0768906 | AE34: =cFactors!AE35 -> 1.1038129 | AF34: =cFactors!AF35 -> 1.1314082 | AG34: =cFactors!AG35 -> 1.1596934 | AH34: =cFactors!AH35 -> 1.1886858 | ... BE34: =cFactors!BE35 -> 2.0975676
F35: =iIndices!F17 -> Other Inflation | G35: % | AA35: =cFactors!AA36 -> 1 | AB35: =cFactors!AB36 -> 1.03 | AC35: =cFactors!AC36 -> 1.0609 | AD35: =cFactors!AD36 -> 1.092727 | AE35: =cFactors!AE36 -> 1.1255088 | AF35: =cFactors!AF36 -> 1.1592741 | AG35: =cFactors!AG36 -> 1.1940523 | AH35: =cFactors!AH36 -> 1.2298739 | ... BE35: =cFactors!BE36 -> 2.4272625
F36: =iIndices!F18 -> Inflation Type C | G36: % | AA36: =cFactors!AA37 -> 1 | AB36: =cFactors!AB37 -> 1.02 | AC36: =cFactors!AC37 -> 1.0404 | AD36: =cFactors!AD37 -> 1.061208 | AE36: =cFactors!AE37 -> 1.0824322 | AF36: =cFactors!AF37 -> 1.1040808 | AG36: =cFactors!AG37 -> 1.1261624 | AH36: =cFactors!AH37 -> 1.1486857 | ... BE36: =cFactors!BE37 -> 1.8113616
F37: =iIndices!F19 -> Inflation Type D | G37: % | AA37: =cFactors!AA38 -> 1 | AB37: =cFactors!AB38 -> 1.02 | AC37: =cFactors!AC38 -> 1.0404 | AD37: =cFactors!AD38 -> 1.061208 | AE37: =cFactors!AE38 -> 1.0824322 | AF37: =cFactors!AF38 -> 1.1040808 | AG37: =cFactors!AG38 -> 1.1261624 | AH37: =cFactors!AH38 -> 1.1486857 | ... BE37: =cFactors!BE38 -> 1.8113616
F38: =iIndices!F20 -> Inflation Type E | G38: % | AA38: =cFactors!AA39 -> 1 | AB38: =cFactors!AB39 -> 1.02 | AC38: =cFactors!AC39 -> 1.0404 | AD38: =cFactors!AD39 -> 1.061208 | AE38: =cFactors!AE39 -> 1.0824322 | AF38: =cFactors!AF39 -> 1.1040808 | AG38: =cFactors!AG39 -> 1.1261624 | AH38: =cFactors!AH39 -> 1.1486857 | ... BE38: =cFactors!BE39 -> 1.8113616
D40: 4 | E40: Operating Costs
E42: 4.1 | F42: Operating Costs
F44: Call-Ups
F46: Cost Per Call Hour | G46: =cstConstantUnit -> £ 2022/23 | K46: {=INDEX(iOptions!$M$115:$O$115,1,ActiveCostScenarioIndex)} -> 30
F47: Annual Call Volume | G47: =cstHours -> Hrs | AA47: =cVolumetrics!AA39 -> 0 | AB47: =cVolumetrics!AB39 -> 90000 | AC47: =cVolumetrics!AC39 -> 90000 | AD47: =cVolumetrics!AD39 -> 90000 | AE47: =cVolumetrics!AE39 -> 90000 | AF47: =cVolumetrics!AF39 -> 90000 | AG47: =cVolumetrics!AG39 -> 90000 | AH47: =cVolumetrics!AH39 -> 90000 | ... BE47: =cVolumetrics!BE39 -> 90000
F49: Calculations (Pre-Inflation)
F51: Annual Call Cost | G51: =cstConstantUnit -> £ 2022/23 | AA51: =AA47*$K46*AA20 -> 0 | AB51: =AB47*$K46*AB20 -> 2700000 | AC51: =AC47*$K46*AC20 -> 2700000 | AD51: =AD47*$K46*AD20 -> 2700000 | AE51: =AE47*$K46*AE20 -> 2700000 | AF51: =AF47*$K46*AF20 -> 2700000 | AG51: =AG47*$K46*AG20 -> 2700000 | AH51: =AH47*$K46*AH20 -> 2700000 | ... BE51: =BE47*$K46*BE20 -> 2700000 | BG51: =SUMIFS($AA51:$BE51,$AA$2:$BE$2,">="&BG$2,$AA$3:$BE$3,"<="&BG$3) -> 0 | BH51: =SUMIFS($AA51:$BE51,$AA$2:$BE$2,">="&BH$2,$AA$3:$BE$3,"<="&BH$3) -> 13500000 | BI51: =SUMIFS($AA51:$BE51,$AA$2:$BE$2,">="&BI$2,$AA$3:$BE$3,"<="&BI$3) -> 13500000 | BJ51: =SUMIFS($AA51:$BE51,$AA$2:$BE$2,">="&BJ$2,$AA$3:$BE$3,"<="&BJ$3) -> 13500000 | BK51: =SUMIFS($AA51:$BE51,$AA$2:$BE$2,">="&BK$2,$AA$3:$BE$3,"<="&BK$3) -> 13500000 | BL51: =SUMIFS($AA51:$BE51,$AA$2:$BE$2,">="&BL$2,$AA$3:$BE$3,"<="&BL$3) -> 13500000 | BM51: =SUMIFS($AA51:$BE51,$AA$2:$BE$2,">="&BM$2,$AA$3:$BE$3,"<="&BM$3) -> 13500000
F53: Calculations (Nominal)
F55: Annual Call Cost | G55: =cstNominalUnit -> £ Nominal | I55: =iOptions!Q115 -> Other Inflation | AA55: =AA51*_xlfn.IFNA(INDEX(AA$34:AA$38,MATCH($I55,$F$34:$F$38,0)),0) -> 0 | AB55: =AB51*_xlfn.IFNA(INDEX(AB$34:AB$38,MATCH($I55,$F$34:$F$38,0)),0) -> 2781000 | AC55: =AC51*_xlfn.IFNA(INDEX(AC$34:AC$38,MATCH($I55,$F$34:$F$38,0)),0) -> 2864430 | AD55: =AD51*_xlfn.IFNA(INDEX(AD$34:AD$38,MATCH($I55,$F$34:$F$38,0)),0) -> 2950362.9 | AE55: =AE51*_xlfn.IFNA(INDEX(AE$34:AE$38,MATCH($I55,$F$34:$F$38,0)),0) -> 3038873.8 | AF55: =AF51*_xlfn.IFNA(INDEX(AF$34:AF$38,MATCH($I55,$F$34:$F$38,0)),0) -> 3130040 | AG55: =AG51*_xlfn.IFNA(INDEX(AG$34:AG$38,MATCH($I55,$F$34:$F$38,0)),0) -> 3223941.2 | AH55: =AH51*_xlfn.IFNA(INDEX(AH$34:AH$38,MATCH($I55,$F$34:$F$38,0)),0) -> 3320659.4 | ... BE55: =BE51*_xlfn.IFNA(INDEX(BE$34:BE$38,MATCH($I55,$F$34:$F$38,0)),0) -> 6553608.7 | BG55: =SUMIFS($AA55:$BE55,$AA$2:$BE$2,">="&BG$2,$AA$3:$BE$3,"<="&BG$3) -> 0 | BH55: =SUMIFS($AA55:$BE55,$AA$2:$BE$2,">="&BH$2,$AA$3:$BE$3,"<="&BH$3) -> 14764707 | BI55: =SUMIFS($AA55:$BE55,$AA$2:$BE$2,">="&BI$2,$AA$3:$BE$3,"<="&BI$3) -> 17116342 | BJ55: =SUMIFS($AA55:$BE55,$AA$2:$BE$2,">="&BJ$2,$AA$3:$BE$3,"<="&BJ$3) -> 19842531 | BK55: =SUMIFS($AA55:$BE55,$AA$2:$BE$2,">="&BK$2,$AA$3:$BE$3,"<="&BK$3) -> 23002932 | BL55: =SUMIFS($AA55:$BE55,$AA$2:$BE$2,">="&BL$2,$AA$3:$BE$3,"<="&BL$3) -> 26666703 | BM55: =SUMIFS($AA55:$BE55,$AA$2:$BE$2,">="&BM$2,$AA$3:$BE$3,"<="&BM$3) -> 30914017
D57: 5 | E57: Staff Costs
E59: 5.1 | F59: Agents
F61: Call-Ups
F63: Agents | G63: =cstNum -> # | AA63: =cVolumetrics!AA56 -> 0 | AB63: =cVolumetrics!AB56 -> 58.838912 | AC63: =cVolumetrics!AC56 -> 58.838912 | AD63: =cVolumetrics!AD56 -> 58.838912 | AE63: =cVolumetrics!AE56 -> 58.838912 | AF63: =cVolumetrics!AF56 -> 58.838912 | AG63: =cVolumetrics!AG56 -> 58.838912 | AH63: =cVolumetrics!AH56 -> 58.838912 | ... BE63: =cVolumetrics!BE56 -> 58.838912
F65: Agents Salary Cost | G65: =cstConstantUnit -> £ 2022/23 | K65: {=INDEX(iOptions!$M$49:$O$49,1,ActiveCostScenarioIndex)} -> 29000
F67: Calculations (Pre-Inflation)
...

Sheet cOutputs
C1: THIS CASE STUDY MODEL IS FOR ILLUSTRATIVE PURPOSES
C2: =cstProjectName -> Should Cost Modelling Case Study - Illustrative SCM | Z2: =SysTime!Z2 -> Period Start | AA2: =SysTime!AA2 -> 44652 | AB2: =SysTime!AB2 -> 45017 | AC2: =SysTime!AC2 -> 45383 | AD2: =SysTime!AD2 -> 45748 | AE2: =SysTime!AE2 -> 46113 | AF2: =SysTime!AF2 -> 46478 | AG2: =SysTime!AG2 -> 46844 | ... BE2: =SysTime!BE2 -> 55610 | BG2: =SysTime!BG2 -> 44652 | BH2: =SysTime!BH2 -> 45017 | BI2: =SysTime!BI2 -> 46844 | BJ2: =SysTime!BJ2 -> 48670 | BK2: =SysTime!BK2 -> 50496 | BL2: =SysTime!BL2 -> 52322 | BM2: =SysTime!BM2 -> 54149
C3: =MID(CELL("filename",A1),FIND("]",CELL("filename",A1))+1,256)&" Sheet" -> cOutputs Sheet | Z3: =SysTime!Z3 -> Period End | AA3: =SysTime!AA3 -> 45016 | AB3: =SysTime!AB3 -> 45382 | AC3: =SysTime!AC3 -> 45747 | AD3: =SysTime!AD3 -> 46112 | AE3: =SysTime!AE3 -> 46477 | AF3: =SysTime!AF3 -> 46843 | AG3: =SysTime!AG3 -> 47208 | ... BE3: =SysTime!BE3 -> 55974 | BG3: =SysTime!BG3 -> 45016 | BH3: =SysTime!BH3 -> 46843 | BI3: =SysTime!BI3 -> 48669 | BJ3: =SysTime!BJ3 -> 50495 | BK3: =SysTime!BK3 -> 52321 | BL3: =SysTime!BL3 -> 54148 | BM3: =SysTime!BM3 -> 55974
C4: =IF(ISBLANK(cstProtectiveMarking),"",cstProtectiveMarking) -> Not Protectively Marked | Z4: =SysTime!Z4 -> Timeline | AA4: =SysTime!AA4 -> Annual | AB4: =SysTime!AB4 -> Annual | AC4: =SysTime!AC4 -> Annual | AD4: =SysTime!AD4 -> Annual | AE4: =SysTime!AE4 -> Annual | AF4: =SysTime!AF4 -> Annual | AG4: =SysTime!AG4 -> Annual | ... BE4: =SysTime!BE4 -> Annual | BG4: =SysTime!BG4 -> Annual | BH4: =SysTime!BH4 -> 5 Yearly | BI4: =SysTime!BI4 -> 5 Yearly | BJ4: =SysTime!BJ4 -> 5 Yearly | BK4: =SysTime!BK4 -> 5 Yearly | BL4: =SysTime!BL4 -> 5 Yearly | BM4: =SysTime!BM4 -> 5 Yearly
C5: =HYPERLINK("#'Contents'!A1",sysChkWord) -> All Checks OK | Z5: =SysTime!Z5 -> Period index | AA5: =SysTime!AA5 -> 1 | AB5: =SysTime!AB5 -> 2 | AC5: =SysTime!AC5 -> 3 | AD5: =SysTime!AD5 -> 4 | AE5: =SysTime!AE5 -> 5 | AF5: =SysTime!AF5 -> 6 | AG5: =SysTime!AG5 -> 7 | ... BE5: =SysTime!BE5 -> 31 | BG5: =SysTime!BG5 -> 1 | BH5: =SysTime!BH5 -> 2 | BI5: =SysTime!BI5 -> 3 | BJ5: =SysTime!BJ5 -> 4 | BK5: =SysTime!BK5 -> 5 | BL5: =SysTime!BL5 -> 6 | BM5: =SysTime!BM5 -> 7
C6: =HYPERLINK("#'Contents'!A1","Click for Contents") -> Click for Contents | Z6: =SysTime!Z6 -> Year index | AA6: =SysTime!AA6 -> 1 | AB6: =SysTime!AB6 -> 2 | AC6: =SysTime!AC6 -> 3 | AD6: =SysTime!AD6 -> 4 | AE6: =SysTime!AE6 -> 5 | AF6: =SysTime!AF6 -> 6 | AG6: =SysTime!AG6 -> 7 | ... BE6: =SysTime!BE6 -> 31 | BG6: =SysTime!BG6 -> 0 | BH6: =SysTime!BH6 -> 0 | BI6: =SysTime!BI6 -> 0 | BJ6: =SysTime!BJ6 -> 0 | BK6: =SysTime!BK6 -> 0 | BL6: =SysTime!BL6 -> 0 | BM6: =SysTime!BM6 -> 0
Z7: =SysTime!Z7 -> Relative period | AA7: =SysTime!AA7 -> 1 | AB7: =SysTime!AB7 -> 2 | AC7: =SysTime!AC7 -> 3 | AD7: =SysTime!AD7 -> 4 | AE7: =SysTime!AE7 -> 5 | AF7: =SysTime!AF7 -> 6 | AG7: =SysTime!AG7 -> 7 | ... BE7: =SysTime!BE7 -> 31 | BG7: =SysTime!BG7 -> 1 | BH7: =SysTime!BH7 -> 2 | BI7: =SysTime!BI7 -> 3 | BJ7: =SysTime!BJ7 -> 4 | BK7: =SysTime!BK7 -> 5 | BL7: =SysTime!BL7 -> 6 | BM7: =SysTime!BM7 -> 7
A8: =SUM(A9:A197) -> 0 | B8: =SUM(B9:B197) -> 0 | G8: Units
D10: 1 | E10: Inflation Call-Ups
E12: 1.1 | F12: Discount Factors
F14: Treasury Rates
F16: GDP Deflator (General Price Inflation) | G16: % | AA16: =cFactors!AA45 -> 1 | AB16: =cFactors!AB45 -> 0.98716683 | AC16: =cFactors!AC45 -> 0.97066552 | AD16: =cFactors!AD45 -> 0.95256675 | AE16: =cFactors!AE45 -> 0.93480545 | AF16: =cFactors!AF45 -> 0.91647593 | AG16: =cFactors!AG45 -> 0.89850581 | AH16: =cFactors!AH45 -> 0.88088805 | ... BE16: =cFactors!BE45 -> 0.55862037
F17: Treasury Real Discount Rate | G17: % | AA17: =cFactors!AA46 -> 1 | AB17: =cFactors!AB46 -> 0.96618357 | AC17: =cFactors!AC46 -> 0.9335107 | AD17: =cFactors!AD46 -> 0.90194271 | AE17: =cFactors!AE46 -> 0.87144223 | AF17: =cFactors!AF46 -> 0.84197317 | AG17: =cFactors!AG46 -> 0.81350064 | AH17: =cFactors!AH46 -> 0.78599096 | ... BE17: =cFactors!BE46 -> 0.35800792
D19: 2 | E19: Costs (Nominal)
E21: 2.1 | F21: In year costs
F23: Nominal Costs | I23: 31 Yr Total
F25: Build & Operate | G25: =cstNominalUnit -> £ Nominal | I25: =SUM(AA25:BE25) -> 1.0891999e+08 | AA25: =SUM(AA26:AA31) -> 3045073 | AB25: =SUM(AB26:AB31) -> 2910738.8 | AC25: =SUM(AC26:AC31) -> 2402943.2 | AD25: =SUM(AD26:AD31) -> 2464003.1 | AE25: =SUM(AE26:AE31) -> 2574911.3 | AF25: =SUM(AF26:AF31) -> 2590831.1 | AG25: =SUM(AG26:AG31) -> 2814891.6 | AH25: =SUM(AH26:AH31) -> 2776977 | ... BE25: =SUM(BE26:BE31) -> 4854956.4 | BG25: =SUMIFS($AA25:$BE25,$AA$2:$BE$2,">="&BG$2,$AA$3:$BE$3,"<="&BG$3) -> 3045073 | BH25: =SUMIFS($AA25:$BE25,$AA$2:$BE$2,">="&BH$2,$AA$3:$BE$3,"<="&BH$3) -> 12943427 | BI25: =SUMIFS($AA25:$BE25,$AA$2:$BE$2,">="&BI$2,$AA$3:$BE$3,"<="&BI$3) -> 14244752 | BJ25: =SUMIFS($AA25:$BE25,$AA$2:$BE$2,">="&BJ$2,$AA$3:$BE$3,"<="&BJ$3) -> 16091951 | BK25: =SUMIFS($AA25:$BE25,$AA$2:$BE$2,">="&BK$2,$AA$3:$BE$3,"<="&BK$3) -> 18322558 | BL25: =SUMIFS($AA25:$BE25,$AA$2:$BE$2,">="&BL$2,$AA$3:$BE$3,"<="&BL$3) -> 20789389 | BM25: =SUMIFS($AA25:$BE25,$AA$2:$BE$2,">="&BM$2,$AA$3:$BE$3,"<="&BM$3) -> 23482839
F26: Operating Costs | G26: =cstNominalUnit -> £ Nominal | I26: =SUM(AA26:BE26) -> 0 | BG26: =SUMIFS($AA26:$BE26,$AA$2:$BE$2,">="&BG$2,$AA$3:$BE$3,"<="&BG$3) -> 0 | BH26: =SUMIFS($AA26:$BE26,$AA$2:$BE$2,">="&BH$2,$AA$3:$BE$3,"<="&BH$3) -> 0 | BI26: =SUMIFS($AA26:$BE26,$AA$2:$BE$2,">="&BI$2,$AA$3:$BE$3,"<="&BI$3) -> 0 | BJ26: =SUMIFS($AA26:$BE26,$AA$2:$BE$2,">="&BJ$2,$AA$3:$BE$3,"<="&BJ$3) -> 0 | BK26: =SUMIFS($AA26:$BE26,$AA$2:$BE$2,">="&BK$2,$AA$3:$BE$3,"<="&BK$3) -> 0 | BL26: =SUMIFS($AA26:$BE26,$AA$2:$BE$2,">="&BL$2,$AA$3:$BE$3,"<="&BL$3) -> 0 | BM26: =SUMIFS($AA26:$BE26,$AA$2:$BE$2,">="&BM$2,$AA$3:$BE$3,"<="&BM$3) -> 0
F27: Staff Costs | G27: =cstNominalUnit -> £ Nominal | I27: =SUM(AA27:BE27) -> 94472985 | AA27: =cCosts!AA133 -> 0 | AB27: =cCosts!AB133 -> 2151871.7 | AC27: =cCosts!AC133 -> 2205668.5 | AD27: =cCosts!AD133 -> 2260810.2 | AE27: =cCosts!AE133 -> 2317330.5 | AF27: =cCosts!AF133 -> 2375263.7 | AG27: =cCosts!AG133 -> 2434645.3 | AH27: =cCosts!AH133 -> 2495511.5 | ... BE27: =cCosts!BE133 -> 4403606.2 | BG27: =SUMIFS($AA27:$BE27,$AA$2:$BE$2,">="&BG$2,$AA$3:$BE$3,"<="&BG$3) -> 0 | BH27: =SUMIFS($AA27:$BE27,$AA$2:$BE$2,">="&BH$2,$AA$3:$BE$3,"<="&BH$3) -> 11310945 | BI27: =SUMIFS($AA27:$BE27,$AA$2:$BE$2,">="&BI$2,$AA$3:$BE$3,"<="&BI$3) -> 12797296 | BJ27: =SUMIFS($AA27:$BE27,$AA$2:$BE$2,">="&BJ$2,$AA$3:$BE$3,"<="&BJ$3) -> 14478965 | BK27: =SUMIFS($AA27:$BE27,$AA$2:$BE$2,">="&BK$2,$AA$3:$BE$3,"<="&BK$3) -> 16381620 | BL27: =SUMIFS($AA27:$BE27,$AA$2:$BE$2,">="&BL$2,$AA$3:$BE$3,"<="&BL$3) -> 18534300 | BM27: =SUMIFS($AA27:$BE27,$AA$2:$BE$2,">="&BM$2,$AA$3:$BE$3,"<="&BM$3) -> 20969859
F28: Software & Hardware Costs | G28: =cstNominalUnit -> £ Nominal | I28: =SUM(AA28:BE28) -> 9930144 | AA28: =cCosts!AA293 -> 0 | AB28: =cCosts!AB293 -> 727931.17 | AC28: =cCosts!AC293 -> 165410.73 | AD28: =cCosts!AD293 -> 170373.06 | AE28: =cCosts!AE293 -> 223776.35 | AF28: =cCosts!AF293 -> 180748.78 | AG28: =cCosts!AG293 -> 344383.17 | AH28: =cCosts!AH293 -> 244526.46 | ... BE28: =cCosts!BE293 -> 378447.8 | BG28: =SUMIFS($AA28:$BE28,$AA$2:$BE$2,">="&BG$2,$AA$3:$BE$3,"<="&BG$3) -> 0 | BH28: =SUMIFS($AA28:$BE28,$AA$2:$BE$2,">="&BH$2,$AA$3:$BE$3,"<="&BH$3) -> 1468240.1 | BI28: =SUMIFS($AA28:$BE28,$AA$2:$BE$2,">="&BI$2,$AA$3:$BE$3,"<="&BI$3) -> 1257053.7 | BJ28: =SUMIFS($AA28:$BE28,$AA$2:$BE$2,">="&BJ$2,$AA$3:$BE$3,"<="&BJ$3) -> 1392257.4 | BK28: =SUMIFS($AA28:$BE28,$AA$2:$BE$2,">="&BK$2,$AA$3:$BE$3,"<="&BK$3) -> 1685052.3 | BL28: =SUMIFS($AA28:$BE28,$AA$2:$BE$2,">="&BL$2,$AA$3:$BE$3,"<="&BL$3) -> 1958448.7 | BM28: =SUMIFS($AA28:$BE28,$AA$2:$BE$2,">="&BM$2,$AA$3:$BE$3,"<="&BM$3) -> 2169091.7
F29: Lease Costs | G29: =cstNominalUnit -> £ Nominal | I29: =SUM(AA29:BE29) -> 0 | BG29: =SUMIFS($AA29:$BE29,$AA$2:$BE$2,">="&BG$2,$AA$3:$BE$3,"<="&BG$3) -> 0 | BH29: =SUMIFS($AA29:$BE29,$AA$2:$BE$2,">="&BH$2,$AA$3:$BE$3,"<="&BH$3) -> 0 | BI29: =SUMIFS($AA29:$BE29,$AA$2:$BE$2,">="&BI$2,$AA$3:$BE$3,"<="&BI$3) -> 0 | BJ29: =SUMIFS($AA29:$BE29,$AA$2:$BE$2,">="&BJ$2,$AA$3:$BE$3,"<="&BJ$3) -> 0 | BK29: =SUMIFS($AA29:$BE29,$AA$2:$BE$2,">="&BK$2,$AA$3:$BE$3,"<="&BK$3) -> 0 | BL29: =SUMIFS($AA29:$BE29,$AA$2:$BE$2,">="&BL$2,$AA$3:$BE$3,"<="&BL$3) -> 0 | BM29: =SUMIFS($AA29:$BE29,$AA$2:$BE$2,">="&BM$2,$AA$3:$BE$3,"<="&BM$3) -> 0
F30: Build & Maintenance Costs | G30: =cstNominalUnit -> £ Nominal | I30: =SUM(AA30:BE30) -> 4516860.2 | AA30: =cCosts!AA480 -> 3045073 | AB30: =cCosts!AB480 -> 30935.878 | AC30: =cCosts!AC480 -> 31863.954 | AD30: =cCosts!AD480 -> 32819.873 | AE30: =cCosts!AE480 -> 33804.469 | AF30: =cCosts!AF480 -> 34818.603 | AG30: =cCosts!AG480 -> 35863.161 | AH30: =cCosts!AH480 -> 36939.056 | ... BE30: =cCosts!BE480 -> 72902.422 | BG30: =SUMIFS($AA30:$BE30,$AA$2:$BE$2,">="&BG$2,$AA$3:$BE$3,"<="&BG$3) -> 3045073 | BH30: =SUMIFS($AA30:$BE30,$AA$2:$BE$2,">="&BH$2,$AA$3:$BE$3,"<="&BH$3) -> 164242.78 | BI30: =SUMIFS($AA30:$BE30,$AA$2:$BE$2,">="&BI$2,$AA$3:$BE$3,"<="&BI$3) -> 190402.39 | BJ30: =SUMIFS($AA30:$BE30,$AA$2:$BE$2,">="&BJ$2,$AA$3:$BE$3,"<="&BJ$3) -> 220728.56 | BK30: =SUMIFS($AA30:$BE30,$AA$2:$BE$2,">="&BK$2,$AA$3:$BE$3,"<="&BK$3) -> 255884.89 | BL30: =SUMIFS($AA30:$BE30,$AA$2:$BE$2,">="&BL$2,$AA$3:$BE$3,"<="&BL$3) -> 296640.72 | BM30: =SUMIFS($AA30:$BE30,$AA$2:$BE$2,">="&BM$2,$AA$3:$BE$3,"<="&BM$3) -> 343887.9
F32: Lease & Operate | G32: =cstNominalUnit -> £ Nominal | I32: =SUM(AA32:BE32) -> 1.0678602e+08 | AA32: =SUM(AA33:AA38) -> 0 | AB32: =SUM(AB33:AB38) -> 2929889.5 | AC32: =SUM(AC33:AC38) -> 2422668.5 | AD32: =SUM(AD33:AD38) -> 2484320.2 | AE32: =SUM(AE33:AE38) -> 2595837.9 | AF32: =SUM(AF33:AF38) -> 2612385.5 | AG32: =SUM(AG33:AG38) -> 2837092.7 | AH32: =SUM(AH33:AH38) -> 2799844 | ... BE32: =SUM(BE33:BE38) -> 4900086.5 | BG32: =SUMIFS($AA32:$BE32,$AA$2:$BE$2,">="&BG$2,$AA$3:$BE$3,"<="&BG$3) -> 0 | BH32: =SUMIFS($AA32:$BE32,$AA$2:$BE$2,">="&BH$2,$AA$3:$BE$3,"<="&BH$3) -> 13045102 | BI32: =SUMIFS($AA32:$BE32,$AA$2:$BE$2,">="&BI$2,$AA$3:$BE$3,"<="&BI$3) -> 14362620 | BJ32: =SUMIFS($AA32:$BE32,$AA$2:$BE$2,">="&BJ$2,$AA$3:$BE$3,"<="&BJ$3) -> 16228593 | BK32: =SUMIFS($AA32:$BE32,$AA$2:$BE$2,">="&BK$2,$AA$3:$BE$3,"<="&BK$3) -> 18480962 | BL32: =SUMIFS($AA32:$BE32,$AA$2:$BE$2,">="&BL$2,$AA$3:$BE$3,"<="&BL$3) -> 20973024 | BM32: =SUMIFS($AA32:$BE32,$AA$2:$BE$2,">="&BM$2,$AA$3:$BE$3,"<="&BM$3) -> 23695722
F33: Operating Costs | G33: =cstNominalUnit -> £ Nominal | I33: =SUM(AA33:BE33) -> 0 | BG33: =SUMIFS($AA33:$BE33,$AA$2:$BE$2,">="&BG$2,$AA$3:$BE$3,"<="&BG$3) -> 0 | BH33: =SUMIFS($AA33:$BE33,$AA$2:$BE$2,">="&BH$2,$AA$3:$BE$3,"<="&BH$3) -> 0 | BI33: =SUMIFS($AA33:$BE33,$AA$2:$BE$2,">="&BI$2,$AA$3:$BE$3,"<="&BI$3) -> 0 | BJ33: =SUMIFS($AA33:$BE33,$AA$2:$BE$2,">="&BJ$2,$AA$3:$BE$3,"<="&BJ$3) -> 0 | BK33: =SUMIFS($AA33:$BE33,$AA$2:$BE$2,">="&BK$2,$AA$3:$BE$3,"<="&BK$3) -> 0 | BL33: =SUMIFS($AA33:$BE33,$AA$2:$BE$2,">="&BL$2,$AA$3:$BE$3,"<="&BL$3) -> 0 | BM33: =SUMIFS($AA33:$BE33,$AA$2:$BE$2,">="&BM$2,$AA$3:$BE$3,"<="&BM$3) -> 0
F34: Staff Costs | G34: =cstNominalUnit -> £ Nominal | I34: =SUM(AA34:BE34) -> 94472985 | AA34: =cCosts!AA133 -> 0 | AB34: =cCosts!AB133 -> 2151871.7 | AC34: =cCosts!AC133 -> 2205668.5 | AD34: =cCosts!AD133 -> 2260810.2 | AE34: =cCosts!AE133 -> 2317330.5 | AF34: =cCosts!AF133 -> 2375263.7 | AG34: =cCosts!AG133 -> 2434645.3 | AH34: =cCosts!AH133 -> 2495511.5 | ... BE34: =cCosts!BE133 -> 4403606.2 | BG34: =SUMIFS($AA34:$BE34,$AA$2:$BE$2,">="&BG$2,$AA$3:$BE$3,"<="&BG$3) -> 0 | BH34: =SUMIFS($AA34:$BE34,$AA$2:$BE$2,">="&BH$2,$AA$3:$BE$3,"<="&BH$3) -> 11310945 | BI34: =SUMIFS($AA34:$BE34,$AA$2:$BE$2,">="&BI$2,$AA$3:$BE$3,"<="&BI$3) -> 12797296 | BJ34: =SUMIFS($AA34:$BE34,$AA$2:$BE$2,">="&BJ$2,$AA$3:$BE$3,"<="&BJ$3) -> 14478965 | BK34: =SUMIFS($AA34:$BE34,$AA$2:$BE$2,">="&BK$2,$AA$3:$BE$3,"<="&BK$3) -> 16381620 | BL34: =SUMIFS($AA34:$BE34,$AA$2:$BE$2,">="&BL$2,$AA$3:$BE$3,"<="&BL$3) -> 18534300 | BM34: =SUMIFS($AA34:$BE34,$AA$2:$BE$2,">="&BM$2,$AA$3:$BE$3,"<="&BM$3) -> 20969859
F35: Software & Hardware Costs | G35: =cstNominalUnit -> £ Nominal | I35: =SUM(AA35:BE35) -> 9930144 | AA35: =cCosts!AA293 -> 0 | AB35: =cCosts!AB293 -> 727931.17 | AC35: =cCosts!AC293 -> 165410.73 | AD35: =cCosts!AD293 -> 170373.06 | AE35: =cCosts!AE293 -> 223776.35 | AF35: =cCosts!AF293 -> 180748.78 | AG35: =cCosts!AG293 -> 344383.17 | AH35: =cCosts!AH293 -> 244526.46 | ... BE35: =cCosts!BE293 -> 378447.8 | BG35: =SUMIFS($AA35:$BE35,$AA$2:$BE$2,">="&BG$2,$AA$3:$BE$3,"<="&BG$3) -> 0 | BH35: =SUMIFS($AA35:$BE35,$AA$2:$BE$2,">="&BH$2,$AA$3:$BE$3,"<="&BH$3) -> 1468240.1 | BI35: =SUMIFS($AA35:$BE35,$AA$2:$BE$2,">="&BI$2,$AA$3:$BE$3,"<="&BI$3) -> 1257053.7 | BJ35: =SUMIFS($AA35:$BE35,$AA$2:$BE$2,">="&BJ$2,$AA$3:$BE$3,"<="&BJ$3) -> 1392257.4 | BK35: =SUMIFS($AA35:$BE35,$AA$2:$BE$2,">="&BK$2,$AA$3:$BE$3,"<="&BK$3) -> 1685052.3 | BL35: =SUMIFS($AA35:$BE35,$AA$2:$BE$2,">="&BL$2,$AA$3:$BE$3,"<="&BL$3) -> 1958448.7 | BM35: =SUMIFS($AA35:$BE35,$AA$2:$BE$2,">="&BM$2,$AA$3:$BE$3,"<="&BM$3) -> 2169091.7
F36: Lease Costs | G36: =cstNominalUnit -> £ Nominal | I36: =SUM(AA36:BE36) -> 2382893.6 | AA36: =cCosts!AA313 -> 0 | AB36: =cCosts!AB313 -> 50086.659 | AC36: =cCosts!AC313 -> 51589.259 | AD36: =cCosts!AD313 -> 53136.937 | AE36: =cCosts!AE313 -> 54731.045 | AF36: =cCosts!AF313 -> 56372.976 | AG36: =cCosts!AG313 -> 58064.165 | AH36: =cCosts!AH313 -> 59806.09 | ... BE36: =cCosts!BE313 -> 118032.49 | BG36: =SUMIFS($AA36:$BE36,$AA$2:$BE$2,">="&BG$2,$AA$3:$BE$3,"<="&BG$3) -> 0 | BH36: =SUMIFS($AA36:$BE36,$AA$2:$BE$2,">="&BH$2,$AA$3:$BE$3,"<="&BH$3) -> 265916.87 | BI36: =SUMIFS($AA36:$BE36,$AA$2:$BE$2,">="&BI$2,$AA$3:$BE$3,"<="&BI$3) -> 308270.54 | BJ36: =SUMIFS($AA36:$BE36,$AA$2:$BE$2,">="&BJ$2,$AA$3:$BE$3,"<="&BJ$3) -> 357370.04 | BK36: =SUMIFS($AA36:$BE36,$AA$2:$BE$2,">="&BK$2,$AA$3:$BE$3,"<="&BK$3) -> 414289.83 | BL36: =SUMIFS($AA36:$BE36,$AA$2:$BE$2,">="&BL$2,$AA$3:$BE$3,"<="&BL$3) -> 480275.46 | BM36: =SUMIFS($AA36:$BE36,$AA$2:$BE$2,">="&BM$2,$AA$3:$BE$3,"<="&BM$3) -> 556770.88
F37: Build & Maintenance Costs | G37: =cstNominalUnit -> £ Nominal | I37: =SUM(AA37:BE37) -> 0 | BG37: =SUMIFS($AA37:$BE37,$AA$2:$BE$2,">="&BG$2,$AA$3:$BE$3,"<="&BG$3) -> 0 | BH37: =SUMIFS($AA37:$BE37,$AA$2:$BE$2,">="&BH$2,$AA$3:$BE$3,"<="&BH$3) -> 0 | BI37: =SUMIFS($AA37:$BE37,$AA$2:$BE$2,">="&BI$2,$AA$3:$BE$3,"<="&BI$3) -> 0 | BJ37: =SUMIFS($AA37:$BE37,$AA$2:$BE$2,">="&BJ$2,$AA$3:$BE$3,"<="&BJ$3) -> 0 | BK37: =SUMIFS($AA37:$BE37,$AA$2:$BE$2,">="&BK$2,$AA$3:$BE$3,"<="&BK$3) -> 0 | BL37: =SUMIFS($AA37:$BE37,$AA$2:$BE$2,">="&BL$2,$AA$3:$BE$3,"<="&BL$3) -> 0 | BM37: =SUMIFS($AA37:$BE37,$AA$2:$BE$2,">="&BM$2,$AA$3:$BE$3,"<="&BM$3) -> 0
F39: Outsource | G39: =cstNominalUnit -> £ Nominal | I39: =SUM(AA39:BE39) -> 1.3230723e+08 | AA39: =SUM(AA40:AA45) -> 0 | AB39: =SUM(AB40:AB45) -> 2781000 | AC39: =SUM(AC40:AC45) -> 2864430 | AD39: =SUM(AD40:AD45) -> 2950362.9 | AE39: =SUM(AE40:AE45) -> 3038873.8 | AF39: =SUM(AF40:AF45) -> 3130040 | AG39: =SUM(AG40:AG45) -> 3223941.2 | AH39: =SUM(AH40:AH45) -> 3320659.4 | ... BE39: =SUM(BE40:BE45) -> 6553608.7 | BG39: =SUMIFS($AA39:$BE39,$AA$2:$BE$2,">="&BG$2,$AA$3:$BE$3,"<="&BG$3) -> 0 | BH39: =SUMIFS($AA39:$BE39,$AA$2:$BE$2,">="&BH$2,$AA$3:$BE$3,"<="&BH$3) -> 14764707 | BI39: =SUMIFS($AA39:$BE39,$AA$2:$BE$2,">="&BI$2,$AA$3:$BE$3,"<="&BI$3) -> 17116342 | BJ39: =SUMIFS($AA39:$BE39,$AA$2:$BE$2,">="&BJ$2,$AA$3:$BE$3,"<="&BJ$3) -> 19842531 | BK39: =SUMIFS($AA39:$BE39,$AA$2:$BE$2,">="&BK$2,$AA$3:$BE$3,"<="&BK$3) -> 23002932 | BL39: =SUMIFS($AA39:$BE39,$AA$2:$BE$2,">="&BL$2,$AA$3:$BE$3,"<="&BL$3) -> 26666703 | BM39: =SUMIFS($AA39:$BE39,$AA$2:$BE$2,">="&BM$2,$AA$3:$BE$3,"<="&BM$3) -> 30914017
